Workbook

Sheet Consolidado
C2: CashFlow | OG2: ORÇADO
C3: Consolidado | E3: 46023 | F3: =E3+1 -> 46024 | G3: =F3+1 -> 46025 | H3: =G3+1 -> 46026 | I3: =H3+1 -> 46027 | J3: =I3+1 -> 46028 | K3: =J3+1 -> 46029 | L3: =K3+1 -> 46030 | M3: =L3+1 -> 46031 | ... AI3: =AH3+1 -> 46053 | AJ3: Jan-26 | AK3: =AI3+1 -> 46054 | AL3: =AK3+1 -> 46055 | AM3: =AL3+1 -> 46056 | AN3: =AM3+1 -> 46057 | AO3: =AN3+1 -> 46058 | AP3: =AO3+1 -> 46059 | AQ3: =AP3+1 -> 46060 | AR3: =AQ3+1 -> 46061 | AS3: =AR3+1 -> 46062 | ... BL3: =BK3+1 -> 46081 | BP3: Fev-26 | BQ3: =BL3+1 -> 46082 | BR3: =BQ3+1 -> 46083 | BS3: =BR3+1 -> 46084 | BT3: =BS3+1 -> 46085 | BU3: =BT3+1 -> 46086 | BV3: =BU3+1 -> 46087 | BW3: =BV3+1 -> 46088 | BX3: =BW3+1 -> 46089 | BY3: =BX3+1 -> 46090 | ... CU3: =CT3+1 -> 46112 | CV3: Mar-26 | CW3: =CU3+1 -> 46113 | CX3: =CW3+1 -> 46114 | CY3: =CX3+1 -> 46115 | CZ3: =CY3+1 -> 46116 | DA3: =CZ3+1 -> 46117 | DB3: =DA3+1 -> 46118 | DC3: =DB3+1 -> 46119 | DD3: =DC3+1 -> 46120 | DE3: =DD3+1 -> 46121 | ... DZ3: =DY3+1 -> 46142 | EB3: Abr-26 | EC3: =DZ3+1 -> 46143 | ED3: =EC3+1 -> 46144 | EE3: =ED3+1 -> 46145 | EF3: =EE3+1 -> 46146 | EG3: =EF3+1 -> 46147 | EH3: =EG3+1 -> 46148 | EI3: =EH3+1 -> 46149 | EJ3: =EI3+1 -> 46150 | EK3: =EJ3+1 -> 46151 | ... FG3: =FF3+1 -> 46173 | FH3: Mai-26 | FI3: =FG3+1 -> 46174 | FJ3: =FI3+1 -> 46175 | FK3: =FJ3+1 -> 46176 | FL3: =FK3+1 -> 46177 | FM3: =FL3+1 -> 46178 | FN3: =FM3+1 -> 46179 | FO3: =FN3+1 -> 46180 | FP3: =FO3+1 -> 46181 | FQ3: =FP3+1 -> 46182 | ... GL3: =GK3+1 -> 46203 | GN3: Jun-26 | GO3: =GL3+1 -> 46204 | GP3: =GO3+1 -> 46205 | GQ3: =GP3+1 -> 46206 | GR3: =GQ3+1 -> 46207 | GS3: =GR3+1 -> 46208 | GT3: =GS3+1 -> 46209 | GU3: =GT3+1 -> 46210 | GV3: =GU3+1 -> 46211 | GW3: =GV3+1 -> 46212 | ... HS3: =HR3+1 -> 46234 | HT3: Jul-26 | HU3: =HS3+1 -> 46235 | HV3: =HU3+1 -> 46236 | HW3: =HV3+1 -> 46237 | HX3: =HW3+1 -> 46238 | HY3: =HX3+1 -> 46239 | HZ3: =HY3+1 -> 46240 | IA3: =HZ3+1 -> 46241 | IB3: =IA3+1 -> 46242 | IC3: =IB3+1 -> 46243 | ... IY3: =IX3+1 -> 46265 | IZ3: Ago-26 | JA3: =IY3+1 -> 46266 | JB3: =JA3+1 -> 46267 | JC3: =JB3+1 -> 46268 | JD3: =JC3+1 -> 46269 | JE3: =JD3+1 -> 46270 | JF3: =JE3+1 -> 46271 | JG3: =JF3+1 -> 46272 | JH3: =JG3+1 -> 46273 | JI3: =JH3+1 -> 46274 | ... KD3: =KC3+1 -> 46295 | KF3: Set-26 | KG3: =KD3+1 -> 46296 | KH3: =KG3+1 -> 46297 | KI3: =KH3+1 -> 46298 | KJ3: =KI3+1 -> 46299 | KK3: =KJ3+1 -> 46300 | KL3: =KK3+1 -> 46301 | KM3: =KL3+1 -> 46302 | KN3: =KM3+1 -> 46303 | KO3: =KN3+1 -> 46304 | ... LK3: =LJ3+1 -> 46326 | LL3: Out-26 | LM3: =LK3+1 -> 46327 | LN3: =LM3+1 -> 46328 | LO3: =LN3+1 -> 46329 | LP3: =LO3+1 -> 46330 | LQ3: =LP3+1 -> 46331 | LR3: =LQ3+1 -> 46332 | LS3: =LR3+1 -> 46333 | LT3: =LS3+1 -> 46334 | LU3: =LT3+1 -> 46335 | ... MP3: =MO3+1 -> 46356 | MR3: Nov-26 | MS3: =MP3+1 -> 46357 | MT3: =MS3+1 -> 46358 | MU3: =MT3+1 -> 46359 | MV3: =MU3+1 -> 46360 | MW3: =MV3+1 -> 46361 | MX3: =MW3+1 -> 46362 | MY3: =MX3+1 -> 46363 | MZ3: =MY3+1 -> 46364 | NA3: =MZ3+1 -> 46365 | ... NW3: =NV3+1 -> 46387 | NX3: Dez-26 | NZ3: Acumulado | OA3: Orçado | OB3: Var% | OG3: CONSOLIDADO | OI3: Jan-26 | OJ3: Fev-26 | OK3: Mar-26 | OL3: Abr-26 | OM3: Mai-26 | ON3: Jun-26 | OO3: Jul-26 | OP3: Ago-26 | OQ3: Set-26 | OR3: Out-26 | OS3: Nov-26 | OT3: Dez-26 | OV3: Acumulado
C5: (A) Saldo Inicial | E5: =SUM(LARM:RM!E5) -> 9666474 | F5: =E66 -> 9666474 | G5: =F66 -> 9557534 | H5: =G66 -> 9557534 | I5: =H66 -> 9557534 | J5: =I66 -> 9568564.6 | K5: =J66 -> 9610003.3 | L5: =K66 -> 9600051.9 | M5: =L66 -> 9504902 | ... AI5: =AH66 -> 9402648.5 | AJ5: =E5 -> 9666474 | AK5: =AJ66 -> 9416986.5 | AL5: =AK66 -> 9416986.5 | AM5: =AL66 -> 9317787.7 | AN5: =AM66 -> 9404151 | AO5: =AN66 -> 9421184 | AP5: =AO66 -> 9417996.4 | AQ5: =AP66 -> 9445722.9 | AR5: =AQ66 -> 9445722.9 | ... BO5: =BN66 -> 9434402.6 | BP5: =AK5 -> 9416986.5 | BQ5: =BP66 -> 9434402.6 | BR5: =BQ66 -> 9434402.6 | BS5: =BR66 -> 9281310.6 | BT5: =BS66 -> 9305044.1 | BU5: =BT66 -> 9328619.4 | BV5: =BU66 -> 9322788.6 | BW5: =BV66 -> 9323256.5 | BX5: =BW66 -> 9323256.5 | ... CU5: =CT66 -> 9197990.2 | CV5: =BQ5 -> 9434402.6 | CW5: =CV66 -> 9214203.8 | CX5: =CW66 -> 9073948.1 | CY5: =CX66 -> 9044133.1 | CZ5: =CY66 -> 9044133.1 | DA5: =CZ66 -> 9044133.1 | DB5: =DA66 -> 9044133.1 | DC5: =DB66 -> 9039172.9 | DD5: =DC66 -> 9068507.7 | ... EA5: =DZ66 -> 8963918.1 | EB5: =CW5 -> 9214203.8 | EC5: =EB66 -> 8963918.1 | ED5: =EC66 -> 8963918.1 | EE5: =ED66 -> 8963918.1 | EF5: =EE66 -> 8963918.1 | EG5: =EF66 -> 9250122.9 | EH5: =EG66 -> 9269303.2 | EI5: =EH66 -> 9263341.3 | EJ5: =EI66 -> 9247341.3 | ... FG5: =FF66 -> 8741427.6 | FH5: =EC5 -> 8963918.1 | FI5: =FH66 -> 8766038.4 | FJ5: =FI66 -> 8766038.4 | FK5: =FJ66 -> 8695353.8 | FL5: =FK66 -> 8697984.4 | FM5: =FL66 -> 8707531.4 | FN5: =FM66 -> 8713171.1 | FO5: =FN66 -> 8727890 | FP5: =FO66 -> 8729138.3 | ... GM5: =GL66 -> 8427355.9 | GN5: =FI5 -> 8766038.4 | GO5: =GN66 -> 8427355.9 | GP5: =GO66 -> 8357391.5 | GQ5: =GP66 -> 8361949 | GR5: =GQ66 -> 8373641.3 | GS5: =GR66 -> 8274749.8 | GT5: =GS66 -> 8280143.1 | GU5: =GT66 -> 8285875.4 | GV5: =GU66 -> 8272125.3 | ... HS5: =HR66 -> 8093017.1 | HT5: =GO5 -> 8427355.9 | HU5: =HT66 -> 8115092.3 | HV5: =HU66 -> 8021236.9 | HW5: =HV66 -> 8025881.2 | HX5: =HW66 -> 8028617 | HY5: =HX66 -> 7927869.5 | HZ5: =HY66 -> 7934778.9 | IA5: =HZ66 -> 7950262.7 | IB5: =IA66 -> 7950784.4 | ... IY5: =IX66 -> 7870292.4 | IZ5: =HU5 -> 8115092.3 | JA5: =IZ66 -> 7876475.2 | JB5: =JA66 -> 7804904 | JC5: =JB66 -> 7809073.3 | JD5: =JC66 -> 7820247.7 | JE5: =JD66 -> 7815247.7 | JF5: =JE66 -> 7814020.4 | JG5: =JF66 -> 7831487.3 | JH5: =JG66 -> 7824235.6 | ... KE5: =KD66 -> 7548467.5 | KF5: =JA5 -> 7876475.2 | KG5: =KF66 -> 7548467.5 | KH5: =KG66 -> 7437549.5 | KI5: =KH66 -> 7442107 | KJ5: =KI66 -> 7444554.8 | KK5: =KJ66 -> 7444554.8 | KL5: =KK66 -> 7451982.1 | KM5: =KL66 -> 7445433.6 | KN5: =KM66 -> 7446681.9 | ... LK5: =LJ66 -> 7155969.7 | LL5: =KG5 -> 7548467.5 | LM5: =LL66 -> 7169151.8 | LN5: =LM66 -> 7169151.8 | LO5: =LN66 -> 7173796.1 | LP5: =LO66 -> 7120463.7 | LQ5: =LP66 -> 7110463.7 | LR5: =LQ66 -> 7103162.8 | LS5: =LR66 -> 7113646.6 | LT5: =LS66 -> 7111394.9 | ... MQ5: =MP66 -> 6865375.4 | MR5: =LM5 -> 7169151.8 | MS5: =MR66 -> 6865375.4 | MT5: =MS66 -> 6849936 | MU5: =MT66 -> 6821087.7 | MV5: =MU66 -> 6783055.3 | MW5: =MV66 -> 6782905.3 | MX5: =MW66 -> 6784854.2 | MY5: =MX66 -> 6794809.6 | MZ5: =MY66 -> 6793563.9 | ... NW5: =NV66 -> 6455753 | NX5: =MS5 -> 6865375.4 | NZ5: =AJ5 -> 9666474 | OA5: =NZ5 -> 9666474 | OG5: (A) Saldo Inicial | OI5: =SUM(LARM:RM!OI5) -> 9666474 | OJ5: =SUM(LARM:RM!OJ5) -> 9318743 | OK5: =SUM(LARM:RM!OK5) -> 8870547.8 | OL5: =SUM(LARM:RM!OL5) -> 8557368.7 | OM5: =SUM(LARM:RM!OM5) -> 8201602.8 | ON5: =SUM(LARM:RM!ON5) -> 8044399.7 | OO5: =SUM(LARM:RM!OO5) -> 7825930.4 | OP5: =SUM(LARM:RM!OP5) -> 7637207.4 | ... OT5: =SUM(LARM:RM!OT5) -> 6908418.4 | OV5: =OI5 -> 9666474
B7: 1. | C7: Receitas Brutas | E7: =SUM(E8:E11) -> 0 | F7: =SUM(F8:F11) -> 5609.2 | G7: =SUM(G8:G11) -> 0 | H7: =SUM(H8:H11) -> 0 | I7: =SUM(I8:I11) -> 13569.03 | J7: =SUM(J8:J11) -> 42403.73 | K7: =SUM(K8:K11) -> 6934.1 | L7: =SUM(L8:L11) -> 4030.18 | ... NX7: =SUM(NX8:NX11) -> 252682.25 | NZ7: =SUM(NZ8:NZ11) -> 3893041.9 | OA7: =SUM(OA8:OA12) -> 2409155.6 | OB7: =IF(NZ7=0,"",(OA7/NZ7)-1) -> -0.38116371 | OG7: Receitas Brutas | OI7: =SUM(OI8:OI11) -> 299175.36 | OJ7: =SUM(OJ8:OJ11) -> 283317.91 | OK7: =SUM(OK8:OK11) -> 434755.18 | OL7: =SUM(OL8:OL11) -> 293546.88 | OM7: =SUM(OM8:OM11) -> 299094.24 | ON7: =SUM(ON8:ON11) -> 292750.18 | OO7: =SUM(OO8:OO11) -> 306379.46 | OP7: =SUM(OP8:OP11) -> 450349.35 | ... OT7: =SUM(OT8:OT11) -> 354228.86 | OV7: =SUM(OV8:OV11) -> 4014790.9
B8: 1.1 | C8: VENDA DE IMÓVEIS | E8: =SUM(LARM:RM!E8) -> 0 | F8: =SUM(LARM:RM!F8) -> 5609.2 | G8: =SUM(LARM:RM!G8) -> 0 | H8: =SUM(LARM:RM!H8) -> 0 | I8: =SUM(LARM:RM!I8) -> 13569.03 | J8: =SUM(LARM:RM!J8) -> 23958.84 | K8: =SUM(LARM:RM!K8) -> 6934.1 | L8: =SUM(LARM:RM!L8) -> 4030.18 | ... AI8: =SUM(LARM:RM!AI8) -> 0 | AJ8: =SUM(E8:AI8) -> 418361.73 | AK8: =SUM(LARM:RM!AK8) -> 0 | AL8: =SUM(LARM:RM!AL8) -> 9347.56 | AM8: =SUM(LARM:RM!AM8) -> 10292.91 | AN8: =SUM(LARM:RM!AN8) -> 8088.29 | AO8: =SUM(LARM:RM!AO8) -> 7695.04 | AP8: =SUM(LARM:RM!AP8) -> 33133.79 | AQ8: =SUM(LARM:RM!AQ8) -> 0 | AR8: =SUM(LARM:RM!AR8) -> 0 | ... BO8: =SUM(LARM:RM!BO8) -> 0 | BP8: =SUM(AK8:BO8) -> 398256.39 | BQ8: =SUM(LARM:RM!BQ8) -> 0 | BR8: =SUM(LARM:RM!BR8) -> 36807.75 | BS8: =SUM(LARM:RM!BS8) -> 27849.87 | BT8: =SUM(LARM:RM!BT8) -> 14642.8 | BU8: =SUM(LARM:RM!BU8) -> 4859.71 | BV8: =SUM(LARM:RM!BV8) -> 9360.65 | BW8: =SUM(LARM:RM!BW8) -> 0 | BX8: =SUM(LARM:RM!BX8) -> 0 | ... CU8: =SUM(LARM:RM!CU8) -> 19943.86 | CV8: =SUM(BQ8:CU8) -> 372283.26 | CW8: =SUM(LARM:RM!CW8) -> 9784.64 | CX8: =SUM(LARM:RM!CX8) -> 6922.99 | CY8: =SUM(LARM:RM!CY8) -> 0 | CZ8: =SUM(LARM:RM!CZ8) -> 0 | DA8: =SUM(LARM:RM!DA8) -> 0 | DB8: =SUM(LARM:RM!DB8) -> 12193.84 | DC8: =SUM(LARM:RM!DC8) -> 29361.82 | DD8: =SUM(LARM:RM!DD8) -> 3663.6 | ... EA8: =SUM(LARM:RM!EA8) -> 0 | EB8: =SUM(CW8:EA8) -> 448049.92 | EC8: =SUM(LARM:RM!EC8) -> 0 | ED8: =SUM(LARM:RM!ED8) -> 0 | EE8: =SUM(LARM:RM!EE8) -> 0 | EF8: =SUM(LARM:RM!EF8) -> 21700.89 | EG8: =SUM(LARM:RM!EG8) -> 20376.6 | EH8: =SUM(LARM:RM!EH8) -> 29823.73 | EI8: =SUM(LARM:RM!EI8) -> 0 | EJ8: =SUM(LARM:RM!EJ8) -> 0 | ... FG8: =SUM(LARM:RM!FG8) -> 0 | FH8: =SUM(EC8:FG8) -> 252021.25 | FI8: =SUM(LARM:RM!FI8) -> 0 | FJ8: =SUM(LARM:RM!FJ8) -> 4644.29 | FK8: =SUM(LARM:RM!FK8) -> 3253.76 | FL8: =SUM(LARM:RM!FL8) -> 1108.49 | FM8: =SUM(LARM:RM!FM8) -> 6790.75 | FN8: =SUM(LARM:RM!FN8) -> 5732.34 | FO8: =SUM(LARM:RM!FO8) -> 1248.33 | FP8: =SUM(LARM:RM!FP8) -> 2185.4 | ... GM8: =SUM(LARM:RM!GM8) -> 0 | GN8: =SUM(FI8:GM8) -> 208446.75 | GO8: =SUM(LARM:RM!GO8) -> 0 | GP8: =SUM(LARM:RM!GP8) -> 4644.29 | GQ8: =SUM(LARM:RM!GQ8) -> 3253.76 | GR8: =SUM(LARM:RM!GR8) -> 1108.49 | GS8: =SUM(LARM:RM!GS8) -> 6339.9 | GT8: =SUM(LARM:RM!GT8) -> 5732.34 | GU8: =SUM(LARM:RM!GU8) -> 3022.92 | GV8: =SUM(LARM:RM!GV8) -> 2185.4 | ... HS8: =SUM(LARM:RM!HS8) -> 0 | HT8: =SUM(GO8:HS8) -> 216447.7 | HU8: =SUM(LARM:RM!HU8) -> 0 | HV8: =SUM(LARM:RM!HV8) -> 4644.29 | HW8: =SUM(LARM:RM!HW8) -> 2735.83 | HX8: =SUM(LARM:RM!HX8) -> 0 | HY8: =SUM(LARM:RM!HY8) -> 6339.9 | HZ8: =SUM(LARM:RM!HZ8) -> 5732.34 | IA8: =SUM(LARM:RM!IA8) -> 1248.33 | IB8: =SUM(LARM:RM!IB8) -> 2185.4 | ... IY8: =SUM(LARM:RM!IY8) -> 0 | IZ8: =SUM(HU8:IY8) -> 227073.04 | JA8: =SUM(LARM:RM!JA8) -> 0 | JB8: =SUM(LARM:RM!JB8) -> 4644.29 | JC8: =SUM(LARM:RM!JC8) -> 2735.83 | JD8: =SUM(LARM:RM!JD8) -> 0 | JE8: =SUM(LARM:RM!JE8) -> 6339.9 | JF8: =SUM(LARM:RM!JF8) -> 7715.48 | JG8: =SUM(LARM:RM!JG8) -> 1248.33 | JH8: =SUM(LARM:RM!JH8) -> 2185.4 | ... KE8: =SUM(LARM:RM!KE8) -> 0 | KF8: =SUM(JA8:KE8) -> 216974.81 | KG8: =SUM(LARM:RM!KG8) -> 0 | KH8: =SUM(LARM:RM!KH8) -> 4644.29 | KI8: =SUM(LARM:RM!KI8) -> 2735.83 | KJ8: =SUM(LARM:RM!KJ8) -> 0 | KK8: =SUM(LARM:RM!KK8) -> 8373.93 | KL8: =SUM(LARM:RM!KL8) -> 5732.34 | KM8: =SUM(LARM:RM!KM8) -> 1248.33 | KN8: =SUM(LARM:RM!KN8) -> 2185.4 | ... LK8: =SUM(LARM:RM!LK8) -> 0 | LL8: =SUM(KG8:LK8) -> 219850.31 | LM8: =SUM(LARM:RM!LM8) -> 0 | LN8: =SUM(LARM:RM!LN8) -> 4644.29 | LO8: =SUM(LARM:RM!LO8) -> 5072.51 | LP8: =SUM(LARM:RM!LP8) -> 0 | LQ8: =SUM(LARM:RM!LQ8) -> 6339.9 | LR8: =SUM(LARM:RM!LR8) -> 5732.34 | LS8: =SUM(LARM:RM!LS8) -> 1248.33 | LT8: =SUM(LARM:RM!LT8) -> 2185.4 | ... MQ8: =SUM(LARM:RM!MQ8) -> 0 | MR8: =SUM(LM8:MQ8) -> 217996.5 | MS8: =SUM(LARM:RM!MS8) -> 0 | MT8: =SUM(LARM:RM!MT8) -> 7651.39 | MU8: =SUM(LARM:RM!MU8) -> 2735.83 | MV8: =SUM(LARM:RM!MV8) -> 0 | MW8: =SUM(LARM:RM!MW8) -> 6339.9 | MX8: =SUM(LARM:RM!MX8) -> 6640.24 | MY8: =SUM(LARM:RM!MY8) -> 1248.33 | MZ8: =SUM(LARM:RM!MZ8) -> 2185.4 | ... NW8: =SUM(LARM:RM!NW8) -> 0 | NX8: =SUM(MS8:NW8) -> 233050.24 | NZ8: =AJ8+BP8+CV8+EB8+FH8+GN8+HT8+IZ8+KF8+LL8+MR8+NX8 -> 3428811.9 | OA8: =SUM(OI8:OP8) -> 2206375.3 | OB8: =IF(OA8=0,"",(NZ8/OA8)-1) -> 0.55404744 | OG8: VENDA DE IMÓVEIS | OI8: =SUM(LARM:RM!OI8) -> 279600.35 | OJ8: =SUM(LARM:RM!OJ8) -> 263742.9 | OK8: =SUM(LARM:RM!OK8) -> 252200.17 | OL8: =SUM(LARM:RM!OL8) -> 273971.87 | OM8: =SUM(LARM:RM!OM8) -> 275114.79 | ON8: =SUM(LARM:RM!ON8) -> 269166.44 | OO8: =SUM(LARM:RM!OO8) -> 286804.45 | OP8: =SUM(LARM:RM!OP8) -> 305774.34 | ... OT8: =SUM(LARM:RM!OT8) -> 334653.85 | OV8: =SUM(OI8:OT8) -> 3483497.6
B9: 1.2 | C9: ALUGUÉIS | E9: =SUM(LARM:RM!E9) -> 0 | F9: =SUM(LARM:RM!F9) -> 0 | G9: =SUM(LARM:RM!G9) -> 0 | H9: =SUM(LARM:RM!H9) -> 0 | I9: =SUM(LARM:RM!I9) -> 0 | J9: =SUM(LARM:RM!J9) -> 9751.45 | K9: =SUM(LARM:RM!K9) -> 0 | L9: =SUM(LARM:RM!L9) -> 0 | ... AI9: =SUM(LARM:RM!AI9) -> 0 | AJ9: =SUM(E9:AI9) -> 9751.45 | AK9: =SUM(LARM:RM!AK9) -> 0 | AL9: =SUM(LARM:RM!AL9) -> 0 | AM9: =SUM(LARM:RM!AM9) -> 0 | AN9: =SUM(LARM:RM!AN9) -> 0 | AO9: =SUM(LARM:RM!AO9) -> 0 | AP9: =SUM(LARM:RM!AP9) -> 0 | AQ9: =SUM(LARM:RM!AQ9) -> 0 | AR9: =SUM(LARM:RM!AR9) -> 0 | ... BO9: =SUM(LARM:RM!BO9) -> 0 | BP9: =SUM(AK9:BO9) -> 0 | BQ9: =SUM(LARM:RM!BQ9) -> 0 | BR9: =SUM(LARM:RM!BR9) -> 0 | BS9: =SUM(LARM:RM!BS9) -> 0 | BT9: =SUM(LARM:RM!BT9) -> 0 | BU9: =SUM(LARM:RM!BU9) -> 0 | BV9: =SUM(LARM:RM!BV9) -> 9751.45 | BW9: =SUM(LARM:RM!BW9) -> 0 | BX9: =SUM(LARM:RM!BX9) -> 0 | ... CU9: =SUM(LARM:RM!CU9) -> 0 | CV9: =SUM(BQ9:CU9) -> 9751.45 | CW9: =SUM(LARM:RM!CW9) -> 0 | CX9: =SUM(LARM:RM!CX9) -> 0 | CY9: =SUM(LARM:RM!CY9) -> 0 | CZ9: =SUM(LARM:RM!CZ9) -> 0 | DA9: =SUM(LARM:RM!DA9) -> 0 | DB9: =SUM(LARM:RM!DB9) -> 0 | DC9: =SUM(LARM:RM!DC9) -> 0 | DD9: =SUM(LARM:RM!DD9) -> 0 | ... EA9: =SUM(LARM:RM!EA9) -> 0 | EB9: =SUM(CW9:EA9) -> 0 | EC9: =SUM(LARM:RM!EC9) -> 0 | ED9: =SUM(LARM:RM!ED9) -> 0 | EE9: =SUM(LARM:RM!EE9) -> 0 | EF9: =SUM(LARM:RM!EF9) -> 0 | EG9: =SUM(LARM:RM!EG9) -> 0 | EH9: =SUM(LARM:RM!EH9) -> 0 | EI9: =SUM(LARM:RM!EI9) -> 0 | EJ9: =SUM(LARM:RM!EJ9) -> 0 | ... FG9: =SUM(LARM:RM!FG9) -> 0 | FH9: =SUM(EC9:FG9) -> 0 | FI9: =SUM(LARM:RM!FI9) -> 0 | FJ9: =SUM(LARM:RM!FJ9) -> 0 | FK9: =SUM(LARM:RM!FK9) -> 0 | FL9: =SUM(LARM:RM!FL9) -> 0 | FM9: =SUM(LARM:RM!FM9) -> 0 | FN9: =SUM(LARM:RM!FN9) -> 9751.45 | FO9: =SUM(LARM:RM!FO9) -> 0 | FP9: =SUM(LARM:RM!FP9) -> 0 | ... GM9: =SUM(LARM:RM!GM9) -> 0 | GN9: =SUM(FI9:GM9) -> 9751.45 | GO9: =SUM(LARM:RM!GO9) -> 0 | GP9: =SUM(LARM:RM!GP9) -> 0 | GQ9: =SUM(LARM:RM!GQ9) -> 0 | GR9: =SUM(LARM:RM!GR9) -> 0 | GS9: =SUM(LARM:RM!GS9) -> 0 | GT9: =SUM(LARM:RM!GT9) -> 0 | GU9: =SUM(LARM:RM!GU9) -> 0 | GV9: =SUM(LARM:RM!GV9) -> 9751.45 | ... HS9: =SUM(LARM:RM!HS9) -> 0 | HT9: =SUM(GO9:HS9) -> 9751.45 | HU9: =SUM(LARM:RM!HU9) -> 0 | HV9: =SUM(LARM:RM!HV9) -> 0 | HW9: =SUM(LARM:RM!HW9) -> 0 | HX9: =SUM(LARM:RM!HX9) -> 0 | HY9: =SUM(LARM:RM!HY9) -> 0 | HZ9: =SUM(LARM:RM!HZ9) -> 9751.45 | IA9: =SUM(LARM:RM!IA9) -> 0 | IB9: =SUM(LARM:RM!IB9) -> 0 | ... IY9: =SUM(LARM:RM!IY9) -> 0 | IZ9: =SUM(HU9:IY9) -> 9751.45 | JA9: =SUM(LARM:RM!JA9) -> 0 | JB9: =SUM(LARM:RM!JB9) -> 0 | JC9: =SUM(LARM:RM!JC9) -> 0 | JD9: =SUM(LARM:RM!JD9) -> 0 | JE9: =SUM(LARM:RM!JE9) -> 0 | JF9: =SUM(LARM:RM!JF9) -> 9751.45 | JG9: =SUM(LARM:RM!JG9) -> 0 | JH9: =SUM(LARM:RM!JH9) -> 0 | ... KE9: =SUM(LARM:RM!KE9) -> 0 | KF9: =SUM(JA9:KE9) -> 9751.45 | KG9: =SUM(LARM:RM!KG9) -> 0 | KH9: =SUM(LARM:RM!KH9) -> 0 | KI9: =SUM(LARM:RM!KI9) -> 0 | KJ9: =SUM(LARM:RM!KJ9) -> 0 | KK9: =SUM(LARM:RM!KK9) -> 0 | KL9: =SUM(LARM:RM!KL9) -> 9751.45 | KM9: =SUM(LARM:RM!KM9) -> 0 | KN9: =SUM(LARM:RM!KN9) -> 0 | ... LK9: =SUM(LARM:RM!LK9) -> 0 | LL9: =SUM(KG9:LK9) -> 9751.45 | LM9: =SUM(LARM:RM!LM9) -> 0 | LN9: =SUM(LARM:RM!LN9) -> 0 | LO9: =SUM(LARM:RM!LO9) -> 0 | LP9: =SUM(LARM:RM!LP9) -> 0 | LQ9: =SUM(LARM:RM!LQ9) -> 0 | LR9: =SUM(LARM:RM!LR9) -> 9751.45 | LS9: =SUM(LARM:RM!LS9) -> 0 | LT9: =SUM(LARM:RM!LT9) -> 0 | ... MQ9: =SUM(LARM:RM!MQ9) -> 0 | MR9: =SUM(LM9:MQ9) -> 9751.45 | MS9: =SUM(LARM:RM!MS9) -> 0 | MT9: =SUM(LARM:RM!MT9) -> 0 | MU9: =SUM(LARM:RM!MU9) -> 0 | MV9: =SUM(LARM:RM!MV9) -> 0 | MW9: =SUM(LARM:RM!MW9) -> 0 | MX9: =SUM(LARM:RM!MX9) -> 9751.45 | MY9: =SUM(LARM:RM!MY9) -> 0 | MZ9: =SUM(LARM:RM!MZ9) -> 0 | ... NW9: =SUM(LARM:RM!NW9) -> 0 | NX9: =SUM(MS9:NW9) -> 9751.45 | NZ9: =AJ9+BP9+CV9+EB9+FH9+GN9+HT9+IZ9+KF9+LL9+MR9+NX9 -> 87763.05 | OA9: =SUM(OI9:OP9) -> 78011.6 | OB9: =IF(OA9=0,"",(NZ9/OA9)-1) -> 0.125 | OG9: ALUGUÉIS | OI9: =SUM(LARM:RM!OI9) -> 9751.45 | OJ9: =SUM(LARM:RM!OJ9) -> 9751.45 | OK9: =SUM(LARM:RM!OK9) -> 9751.45 | OL9: =SUM(LARM:RM!OL9) -> 9751.45 | OM9: =SUM(LARM:RM!OM9) -> 9751.45 | ON9: =SUM(LARM:RM!ON9) -> 9751.45 | OO9: =SUM(LARM:RM!OO9) -> 9751.45 | OP9: =SUM(LARM:RM!OP9) -> 9751.45 | ... OT9: =SUM(LARM:RM!OT9) -> 9751.45 | OV9: =SUM(OI9:OT9) -> 117017.4
B10: 1.3 | C10: VENDA DE MERCADORIAS/GADO | E10: =SUM(LARM:RM!E10) -> 0 | F10: =SUM(LARM:RM!F10) -> 0 | G10: =SUM(LARM:RM!G10) -> 0 | H10: =SUM(LARM:RM!H10) -> 0 | I10: =SUM(LARM:RM!I10) -> 0 | J10: =SUM(LARM:RM!J10) -> 0 | K10: =SUM(LARM:RM!K10) -> 0 | L10: =SUM(LARM:RM!L10) -> 0 | ... AI10: =SUM(LARM:RM!AI10) -> 0 | AJ10: =SUM(E10:AI10) -> 50000 | AK10: =SUM(LARM:RM!AK10) -> 0 | AL10: =SUM(LARM:RM!AL10) -> 0 | AM10: =SUM(LARM:RM!AM10) -> 77500 | AN10: =SUM(LARM:RM!AN10) -> 0 | AO10: =SUM(LARM:RM!AO10) -> 0 | AP10: =SUM(LARM:RM!AP10) -> 0 | AQ10: =SUM(LARM:RM!AQ10) -> 0 | AR10: =SUM(LARM:RM!AR10) -> 0 | ... BO10: =SUM(LARM:RM!BO10) -> 0 | BP10: =SUM(AK10:BO10) -> 77500 | BQ10: =SUM(LARM:RM!BQ10) -> 0 | BR10: =SUM(LARM:RM!BR10) -> 0 | BS10: =SUM(LARM:RM!BS10) -> 0 | BT10: =SUM(LARM:RM!BT10) -> 0 | BU10: =SUM(LARM:RM!BU10) -> 0 | BV10: =SUM(LARM:RM!BV10) -> 0 | BW10: =SUM(LARM:RM!BW10) -> 0 | BX10: =SUM(LARM:RM!BX10) -> 0 | ... CU10: =SUM(LARM:RM!CU10) -> 0 | CV10: =SUM(BQ10:CU10) -> 0 | CW10: =SUM(LARM:RM!CW10) -> 0 | CX10: =SUM(LARM:RM!CX10) -> 0 | CY10: =SUM(LARM:RM!CY10) -> 0 | CZ10: =SUM(LARM:RM!CZ10) -> 0 | DA10: =SUM(LARM:RM!DA10) -> 0 | DB10: =SUM(LARM:RM!DB10) -> 0 | DC10: =SUM(LARM:RM!DC10) -> 0 | DD10: =SUM(LARM:RM!DD10) -> 0 | ... EA10: =SUM(LARM:RM!EA10) -> 0 | EB10: =SUM(CW10:EA10) -> 12000 | EC10: =SUM(LARM:RM!EC10) -> 0 | ED10: =SUM(LARM:RM!ED10) -> 0 | EE10: =SUM(LARM:RM!EE10) -> 0 | EF10: =SUM(LARM:RM!EF10) -> 0 | EG10: =SUM(LARM:RM!EG10) -> 0 | EH10: =SUM(LARM:RM!EH10) -> 0 | EI10: =SUM(LARM:RM!EI10) -> 0 | EJ10: =SUM(LARM:RM!EJ10) -> 0 | ... FG10: =SUM(LARM:RM!FG10) -> 0 | FH10: =SUM(EC10:FG10) -> 0 | FI10: =SUM(LARM:RM!FI10) -> 0 | FJ10: =SUM(LARM:RM!FJ10) -> 0 | FK10: =SUM(LARM:RM!FK10) -> 0 | FL10: =SUM(LARM:RM!FL10) -> 0 | FM10: =SUM(LARM:RM!FM10) -> 0 | FN10: =SUM(LARM:RM!FN10) -> 0 | FO10: =SUM(LARM:RM!FO10) -> 0 | FP10: =SUM(LARM:RM!FP10) -> 0 | ... GM10: =SUM(LARM:RM!GM10) -> 0 | GN10: =SUM(FI10:GM10) -> 0 | GO10: =SUM(LARM:RM!GO10) -> 0 | GP10: =SUM(LARM:RM!GP10) -> 0 | GQ10: =SUM(LARM:RM!GQ10) -> 0 | GR10: =SUM(LARM:RM!GR10) -> 0 | GS10: =SUM(LARM:RM!GS10) -> 0 | GT10: =SUM(LARM:RM!GT10) -> 0 | GU10: =SUM(LARM:RM!GU10) -> 0 | GV10: =SUM(LARM:RM!GV10) -> 0 | ... HS10: =SUM(LARM:RM!HS10) -> 0 | HT10: =SUM(GO10:HS10) -> 0 | HU10: =SUM(LARM:RM!HU10) -> 0 | HV10: =SUM(LARM:RM!HV10) -> 0 | HW10: =SUM(LARM:RM!HW10) -> 0 | HX10: =SUM(LARM:RM!HX10) -> 0 | HY10: =SUM(LARM:RM!HY10) -> 0 | HZ10: =SUM(LARM:RM!HZ10) -> 0 | IA10: =SUM(LARM:RM!IA10) -> 0 | IB10: =SUM(LARM:RM!IB10) -> 0 | ... IY10: =SUM(LARM:RM!IY10) -> 0 | IZ10: =SUM(HU10:IY10) -> 125000 | JA10: =SUM(LARM:RM!JA10) -> 0 | JB10: =SUM(LARM:RM!JB10) -> 0 | JC10: =SUM(LARM:RM!JC10) -> 0 | JD10: =SUM(LARM:RM!JD10) -> 0 | JE10: =SUM(LARM:RM!JE10) -> 0 | JF10: =SUM(LARM:RM!JF10) -> 0 | JG10: =SUM(LARM:RM!JG10) -> 0 | JH10: =SUM(LARM:RM!JH10) -> 0 | ... KE10: =SUM(LARM:RM!KE10) -> 0 | KF10: =SUM(JA10:KE10) -> 0 | KG10: =SUM(LARM:RM!KG10) -> 0 | KH10: =SUM(LARM:RM!KH10) -> 0 | KI10: =SUM(LARM:RM!KI10) -> 0 | KJ10: =SUM(LARM:RM!KJ10) -> 0 | KK10: =SUM(LARM:RM!KK10) -> 0 | KL10: =SUM(LARM:RM!KL10) -> 0 | KM10: =SUM(LARM:RM!KM10) -> 0 | KN10: =SUM(LARM:RM!KN10) -> 0 | ... LK10: =SUM(LARM:RM!LK10) -> 0 | LL10: =SUM(KG10:LK10) -> 0 | LM10: =SUM(LARM:RM!LM10) -> 0 | LN10: =SUM(LARM:RM!LN10) -> 0 | LO10: =SUM(LARM:RM!LO10) -> 0 | LP10: =SUM(LARM:RM!LP10) -> 0 | LQ10: =SUM(LARM:RM!LQ10) -> 0 | LR10: =SUM(LARM:RM!LR10) -> 0 | LS10: =SUM(LARM:RM!LS10) -> 0 | LT10: =SUM(LARM:RM!LT10) -> 0 | ... MQ10: =SUM(LARM:RM!MQ10) -> 0 | MR10: =SUM(LM10:MQ10) -> 0 | MS10: =SUM(LARM:RM!MS10) -> 0 | MT10: =SUM(LARM:RM!MT10) -> 0 | MU10: =SUM(LARM:RM!MU10) -> 0 | MV10: =SUM(LARM:RM!MV10) -> 0 | MW10: =SUM(LARM:RM!MW10) -> 0 | MX10: =SUM(LARM:RM!MX10) -> 0 | MY10: =SUM(LARM:RM!MY10) -> 0 | MZ10: =SUM(LARM:RM!MZ10) -> 0 | ... NW10: =SUM(LARM:RM!NW10) -> 0 | NX10: =SUM(MS10:NW10) -> 0 | NZ10: =AJ10+BP10+CV10+EB10+FH10+GN10+HT10+IZ10+KF10+LL10+MR10+NX10 -> 264500 | OA10: =SUM(OI10:OP10) -> 287980 | OB10: =IF(OA10=0,"",(NZ10/OA10)-1) -> -0.08153344 | OG10: VENDA DE MERCADORIAS/GADO | OI10: =SUM(LARM:RM!OI10) -> 0 | OJ10: =SUM(LARM:RM!OJ10) -> 0 | OK10: =SUM(LARM:RM!OK10) -> 162980 | OL10: =SUM(LARM:RM!OL10) -> 0 | OM10: =SUM(LARM:RM!OM10) -> 0 | ON10: =SUM(LARM:RM!ON10) -> 0 | OO10: =SUM(LARM:RM!OO10) -> 0 | OP10: =SUM(LARM:RM!OP10) -> 125000 | ... OT10: =SUM(LARM:RM!OT10) -> 0 | OV10: =SUM(OI10:OT10) -> 287980
B11: 1.4 | C11: OUTRAS RECEITAS OPERACIONAIS | E11: =SUM(LARM:RM!E11) -> 0 | F11: =SUM(LARM:RM!F11) -> 0 | G11: =SUM(LARM:RM!G11) -> 0 | H11: =SUM(LARM:RM!H11) -> 0 | I11: =SUM(LARM:RM!I11) -> 0 | J11: =SUM(LARM:RM!J11) -> 8693.44 | K11: =SUM(LARM:RM!K11) -> 0 | L11: =SUM(LARM:RM!L11) -> 0 | ... AI11: =SUM(LARM:RM!AI11) -> 0 | AJ11: =SUM(E11:AI11) -> 10135.44 | AK11: =SUM(LARM:RM!AK11) -> 0 | AL11: =SUM(LARM:RM!AL11) -> 0 | AM11: =SUM(LARM:RM!AM11) -> 0 | AN11: =SUM(LARM:RM!AN11) -> 8965.86 | AO11: =SUM(LARM:RM!AO11) -> 0 | AP11: =SUM(LARM:RM!AP11) -> 0 | AQ11: =SUM(LARM:RM!AQ11) -> 0 | AR11: =SUM(LARM:RM!AR11) -> 0 | ... BO11: =SUM(LARM:RM!BO11) -> 0 | BP11: =SUM(AK11:BO11) -> 10408.86 | BQ11: =SUM(LARM:RM!BQ11) -> 0 | BR11: =SUM(LARM:RM!BR11) -> 0 | BS11: =SUM(LARM:RM!BS11) -> 0 | BT11: =SUM(LARM:RM!BT11) -> 8965.86 | BU11: =SUM(LARM:RM!BU11) -> 0 | BV11: =SUM(LARM:RM!BV11) -> 0 | BW11: =SUM(LARM:RM!BW11) -> 0 | BX11: =SUM(LARM:RM!BX11) -> 0 | ... CU11: =SUM(LARM:RM!CU11) -> 0 | CV11: =SUM(BQ11:CU11) -> 10408.86 | CW11: =SUM(LARM:RM!CW11) -> 0 | CX11: =SUM(LARM:RM!CX11) -> 0 | CY11: =SUM(LARM:RM!CY11) -> 0 | CZ11: =SUM(LARM:RM!CZ11) -> 0 | DA11: =SUM(LARM:RM!DA11) -> 0 | DB11: =SUM(LARM:RM!DB11) -> 8965.86 | DC11: =SUM(LARM:RM!DC11) -> 0 | DD11: =SUM(LARM:RM!DD11) -> 0 | ... EA11: =SUM(LARM:RM!EA11) -> 0 | EB11: =SUM(CW11:EA11) -> 10407.86 | EC11: =SUM(LARM:RM!EC11) -> 0 | ED11: =SUM(LARM:RM!ED11) -> 0 | EE11: =SUM(LARM:RM!EE11) -> 0 | EF11: =SUM(LARM:RM!EF11) -> 0 | EG11: =SUM(LARM:RM!EG11) -> 0 | EH11: =SUM(LARM:RM!EH11) -> 0 | EI11: =SUM(LARM:RM!EI11) -> 0 | EJ11: =SUM(LARM:RM!EJ11) -> 0 | ... FG11: =SUM(LARM:RM!FG11) -> 0 | FH11: =SUM(EC11:FG11) -> 1442 | FI11: =SUM(LARM:RM!FI11) -> 0 | FJ11: =SUM(LARM:RM!FJ11) -> 0 | FK11: =SUM(LARM:RM!FK11) -> 0 | FL11: =SUM(LARM:RM!FL11) -> 8438.56 | FM11: =SUM(LARM:RM!FM11) -> 0 | FN11: =SUM(LARM:RM!FN11) -> 0 | FO11: =SUM(LARM:RM!FO11) -> 0 | FP11: =SUM(LARM:RM!FP11) -> 0 | ... GM11: =SUM(LARM:RM!GM11) -> 0 | GN11: =SUM(FI11:GM11) -> 9880.56 | GO11: =SUM(LARM:RM!GO11) -> 0 | GP11: =SUM(LARM:RM!GP11) -> 0 | GQ11: =SUM(LARM:RM!GQ11) -> 8438.56 | GR11: =SUM(LARM:RM!GR11) -> 0 | GS11: =SUM(LARM:RM!GS11) -> 0 | GT11: =SUM(LARM:RM!GT11) -> 0 | GU11: =SUM(LARM:RM!GU11) -> 0 | GV11: =SUM(LARM:RM!GV11) -> 0 | ... HS11: =SUM(LARM:RM!HS11) -> 0 | HT11: =SUM(GO11:HS11) -> 9880.56 | HU11: =SUM(LARM:RM!HU11) -> 0 | HV11: =SUM(LARM:RM!HV11) -> 0 | HW11: =SUM(LARM:RM!HW11) -> 0 | HX11: =SUM(LARM:RM!HX11) -> 0 | HY11: =SUM(LARM:RM!HY11) -> 8438.56 | HZ11: =SUM(LARM:RM!HZ11) -> 0 | IA11: =SUM(LARM:RM!IA11) -> 0 | IB11: =SUM(LARM:RM!IB11) -> 0 | ... IY11: =SUM(LARM:RM!IY11) -> 0 | IZ11: =SUM(HU11:IY11) -> 9880.56 | JA11: =SUM(LARM:RM!JA11) -> 0 | JB11: =SUM(LARM:RM!JB11) -> 0 | JC11: =SUM(LARM:RM!JC11) -> 8438.56 | JD11: =SUM(LARM:RM!JD11) -> 0 | JE11: =SUM(LARM:RM!JE11) -> 0 | JF11: =SUM(LARM:RM!JF11) -> 0 | JG11: =SUM(LARM:RM!JG11) -> 0 | JH11: =SUM(LARM:RM!JH11) -> 0 | ... KE11: =SUM(LARM:RM!KE11) -> 0 | KF11: =SUM(JA11:KE11) -> 9880.56 | KG11: =SUM(LARM:RM!KG11) -> 0 | KH11: =SUM(LARM:RM!KH11) -> 0 | KI11: =SUM(LARM:RM!KI11) -> 8438.56 | KJ11: =SUM(LARM:RM!KJ11) -> 0 | KK11: =SUM(LARM:RM!KK11) -> 0 | KL11: =SUM(LARM:RM!KL11) -> 0 | KM11: =SUM(LARM:RM!KM11) -> 0 | KN11: =SUM(LARM:RM!KN11) -> 0 | ... LK11: =SUM(LARM:RM!LK11) -> 0 | LL11: =SUM(KG11:LK11) -> 9880.56 | LM11: =SUM(LARM:RM!LM11) -> 0 | LN11: =SUM(LARM:RM!LN11) -> 0 | LO11: =SUM(LARM:RM!LO11) -> 8438.56 | LP11: =SUM(LARM:RM!LP11) -> 0 | LQ11: =SUM(LARM:RM!LQ11) -> 0 | LR11: =SUM(LARM:RM!LR11) -> 0 | LS11: =SUM(LARM:RM!LS11) -> 0 | LT11: =SUM(LARM:RM!LT11) -> 0 | ... MQ11: =SUM(LARM:RM!MQ11) -> 0 | MR11: =SUM(LM11:MQ11) -> 9880.56 | MS11: =SUM(LARM:RM!MS11) -> 0 | MT11: =SUM(LARM:RM!MT11) -> 0 | MU11: =SUM(LARM:RM!MU11) -> 8438.56 | MV11: =SUM(LARM:RM!MV11) -> 0 | MW11: =SUM(LARM:RM!MW11) -> 0 | MX11: =SUM(LARM:RM!MX11) -> 0 | MY11: =SUM(LARM:RM!MY11) -> 0 | MZ11: =SUM(LARM:RM!MZ11) -> 0 | ... NW11: =SUM(LARM:RM!NW11) -> 0 | NX11: =SUM(MS11:NW11) -> 9880.56 | NZ11: =AJ11+BP11+CV11+EB11+FH11+GN11+HT11+IZ11+KF11+LL11+MR11+NX11 -> 111966.94 | OA11: =SUM(OI11:OP11) -> 87001.65 | OB11: =IF(OA11=0,"",(NZ11/OA11)-1) -> 0.28695191 | OG11: OUTRAS RECEITAS OPERACIONAIS | OI11: =SUM(LARM:RM!OI11) -> 9823.56 | OJ11: =SUM(LARM:RM!OJ11) -> 9823.56 | OK11: =SUM(LARM:RM!OK11) -> 9823.56 | OL11: =SUM(LARM:RM!OL11) -> 9823.56 | OM11: =SUM(LARM:RM!OM11) -> 14228 | ON11: =SUM(LARM:RM!ON11) -> 13832.29 | OO11: =SUM(LARM:RM!OO11) -> 9823.56 | OP11: =SUM(LARM:RM!OP11) -> 9823.56 | ... OT11: =SUM(LARM:RM!OT11) -> 9823.56 | OV11: =SUM(OI11:OT11) -> 126295.89
C12: Deduções das Receitas | E12: =SUM(E13:E14) -> 0 | F12: =SUM(F13:F14) -> 0 | G12: =SUM(G13:G14) -> 0 | H12: =SUM(H13:H14) -> 0 | I12: =SUM(I13:I14) -> 0 | J12: =SUM(J13:J14) -> 0 | K12: =SUM(K13:K14) -> 0 | L12: =SUM(L13:L14) -> 0 | ... NX12: =SUM(NX13:NX14) -> -7812.9 | NZ12: =SUM(NZ13:NZ14) -> -457666.46 | OA12: =SUM(OA13:OA14)+OA15 -> -250212.96 | OB12: =IF(OA12=0,"",((NZ12/OA12)-1)*-1) -> -0.82910773 | OG12: Deduções das Receitas | OI12: =SUM(OI13:OI14) -> -81795.37 | OJ12: =SUM(OJ13:OJ14) -> -31012.46 | OK12: =SUM(OK13:OK14) -> -14258.97 | OL12: =SUM(OL13:OL14) -> -47277.71 | OM12: =SUM(OM13:OM14) -> -10039.91 | ON12: =SUM(ON13:ON14) -> -11839.47 | OO12: =SUM(OO13:OO14) -> -34432.94 | OP12: =SUM(OP13:OP14) -> -19556.13 | ... OT12: =SUM(OT13:OT14) -> -7812.9 | OV12: =SUM(OV13:OV14) -> -306707.3
B13: 1.9 | C13: VENDAS CANCELADAS | E13: =SUM(LARM:RM!E13) -> 0 | F13: =SUM(LARM:RM!F13) -> 0 | G13: =SUM(LARM:RM!G13) -> 0 | H13: =SUM(LARM:RM!H13) -> 0 | I13: =SUM(LARM:RM!I13) -> 0 | J13: =SUM(LARM:RM!J13) -> 0 | K13: =SUM(LARM:RM!K13) -> 0 | L13: =SUM(LARM:RM!L13) -> 0 | ... AI13: =SUM(LARM:RM!AI13) -> 0 | AJ13: =SUM(E13:AI13) -> -74993.5 | AK13: =SUM(LARM:RM!AK13) -> 0 | AL13: =SUM(LARM:RM!AL13) -> 0 | AM13: =SUM(LARM:RM!AM13) -> 0 | AN13: =SUM(LARM:RM!AN13) -> 0 | AO13: =SUM(LARM:RM!AO13) -> 0 | AP13: =SUM(LARM:RM!AP13) -> 0 | AQ13: =SUM(LARM:RM!AQ13) -> 0 | AR13: =SUM(LARM:RM!AR13) -> 0 | ... BO13: =SUM(LARM:RM!BO13) -> 0 | BP13: =SUM(AK13:BO13) -> 0 | BQ13: =SUM(LARM:RM!BQ13) -> 0 | BR13: =SUM(LARM:RM!BR13) -> -20091.35 | BS13: =SUM(LARM:RM!BS13) -> 0 | BT13: =SUM(LARM:RM!BT13) -> 0 | BU13: =SUM(LARM:RM!BU13) -> 0 | BV13: =SUM(LARM:RM!BV13) -> 0 | BW13: =SUM(LARM:RM!BW13) -> 0 | BX13: =SUM(LARM:RM!BX13) -> 0 | ... CU13: =SUM(LARM:RM!CU13) -> 0 | CV13: =SUM(BQ13:CU13) -> -39188.38 | CW13: =SUM(LARM:RM!CW13) -> 0 | CX13: =SUM(LARM:RM!CX13) -> 0 | CY13: =SUM(LARM:RM!CY13) -> 0 | CZ13: =SUM(LARM:RM!CZ13) -> 0 | DA13: =SUM(LARM:RM!DA13) -> 0 | DB13: =SUM(LARM:RM!DB13) -> 0 | DC13: =SUM(LARM:RM!DC13) -> 0 | DD13: =SUM(LARM:RM!DD13) -> 0 | ... EA13: =SUM(LARM:RM!EA13) -> 0 | EB13: =SUM(CW13:EA13) -> -50391.62 | EC13: =SUM(LARM:RM!EC13) -> 0 | ED13: =SUM(LARM:RM!ED13) -> 0 | EE13: =SUM(LARM:RM!EE13) -> 0 | EF13: =SUM(LARM:RM!EF13) -> 0 | EG13: =SUM(LARM:RM!EG13) -> 0 | EH13: =SUM(LARM:RM!EH13) -> 0 | EI13: =SUM(LARM:RM!EI13) -> 0 | EJ13: =SUM(LARM:RM!EJ13) -> 0 | ... FG13: =SUM(LARM:RM!FG13) -> 0 | FH13: =SUM(EC13:FG13) -> -48578.94 | FI13: =SUM(LARM:RM!FI13) -> 0 | FJ13: =SUM(LARM:RM!FJ13) -> 0 | FK13: =SUM(LARM:RM!FK13) -> 0 | FL13: =SUM(LARM:RM!FL13) -> 0 | FM13: =SUM(LARM:RM!FM13) -> 0 | FN13: =SUM(LARM:RM!FN13) -> 0 | FO13: =SUM(LARM:RM!FO13) -> 0 | FP13: =SUM(LARM:RM!FP13) -> 0 | ... GM13: =SUM(LARM:RM!GM13) -> 0 | GN13: =SUM(FI13:GM13) -> 0 | GO13: =SUM(LARM:RM!GO13) -> 0 | GP13: =SUM(LARM:RM!GP13) -> 0 | GQ13: =SUM(LARM:RM!GQ13) -> 0 | GR13: =SUM(LARM:RM!GR13) -> 0 | GS13: =SUM(LARM:RM!GS13) -> 0 | GT13: =SUM(LARM:RM!GT13) -> 0 | GU13: =SUM(LARM:RM!GU13) -> 0 | GV13: =SUM(LARM:RM!GV13) -> 0 | ... HS13: =SUM(LARM:RM!HS13) -> 0 | HT13: =SUM(GO13:HS13) -> 0 | HU13: =SUM(LARM:RM!HU13) -> 0 | HV13: =SUM(LARM:RM!HV13) -> 0 | HW13: =SUM(LARM:RM!HW13) -> 0 | HX13: =SUM(LARM:RM!HX13) -> 0 | HY13: =SUM(LARM:RM!HY13) -> 0 | HZ13: =SUM(LARM:RM!HZ13) -> 0 | IA13: =SUM(LARM:RM!IA13) -> 0 | IB13: =SUM(LARM:RM!IB13) -> 0 | ... IY13: =SUM(LARM:RM!IY13) -> 0 | IZ13: =SUM(HU13:IY13) -> 0 | JA13: =SUM(LARM:RM!JA13) -> 0 | JB13: =SUM(LARM:RM!JB13) -> 0 | JC13: =SUM(LARM:RM!JC13) -> 0 | JD13: =SUM(LARM:RM!JD13) -> 0 | JE13: =SUM(LARM:RM!JE13) -> 0 | JF13: =SUM(LARM:RM!JF13) -> 0 | JG13: =SUM(LARM:RM!JG13) -> 0 | JH13: =SUM(LARM:RM!JH13) -> 0 | ... KE13: =SUM(LARM:RM!KE13) -> 0 | KF13: =SUM(JA13:KE13) -> 0 | KG13: =SUM(LARM:RM!KG13) -> 0 | KH13: =SUM(LARM:RM!KH13) -> 0 | KI13: =SUM(LARM:RM!KI13) -> 0 | KJ13: =SUM(LARM:RM!KJ13) -> 0 | KK13: =SUM(LARM:RM!KK13) -> 0 | KL13: =SUM(LARM:RM!KL13) -> 0 | KM13: =SUM(LARM:RM!KM13) -> 0 | KN13: =SUM(LARM:RM!KN13) -> 0 | ... LK13: =SUM(LARM:RM!LK13) -> 0 | LL13: =SUM(KG13:LK13) -> 0 | LM13: =SUM(LARM:RM!LM13) -> 0 | LN13: =SUM(LARM:RM!LN13) -> 0 | LO13: =SUM(LARM:RM!LO13) -> 0 | LP13: =SUM(LARM:RM!LP13) -> 0 | LQ13: =SUM(LARM:RM!LQ13) -> 0 | LR13: =SUM(LARM:RM!LR13) -> 0 | LS13: =SUM(LARM:RM!LS13) -> 0 | LT13: =SUM(LARM:RM!LT13) -> 0 | ... MQ13: =SUM(LARM:RM!MQ13) -> 0 | MR13: =SUM(LM13:MQ13) -> 0 | MS13: =SUM(LARM:RM!MS13) -> 0 | MT13: =SUM(LARM:RM!MT13) -> 0 | MU13: =SUM(LARM:RM!MU13) -> 0 | MV13: =SUM(LARM:RM!MV13) -> 0 | MW13: =SUM(LARM:RM!MW13) -> 0 | MX13: =SUM(LARM:RM!MX13) -> 0 | MY13: =SUM(LARM:RM!MY13) -> 0 | MZ13: =SUM(LARM:RM!MZ13) -> 0 | ... NW13: =SUM(LARM:RM!NW13) -> 0 | NX13: =SUM(MS13:NW13) -> 0 | NZ13: =AJ13+BP13+CV13+EB13+FH13+GN13+HT13+IZ13+KF13+LL13+MR13+NX13 -> -213152.44 | OA13: =SUM(OI13:OP13) -> -53251.59 | OB13: =IF(OA13=0,"",((NZ13/OA13)-1)*-1) -> -3.0027432 | OG13: VENDAS CANCELADAS | OI13: =SUM(LARM:RM!OI13) -> -53251.59 | OJ13: =SUM(LARM:RM!OJ13) -> 0 | OK13: =SUM(LARM:RM!OK13) -> 0 | OL13: =SUM(LARM:RM!OL13) -> 0 | OM13: =SUM(LARM:RM!OM13) -> 0 | ON13: =SUM(LARM:RM!ON13) -> 0 | OO13: =SUM(LARM:RM!OO13) -> 0 | OP13: =SUM(LARM:RM!OP13) -> 0 | ... OT13: =SUM(LARM:RM!OT13) -> 0 | OV13: =SUM(OI13:OT13) -> -53251.59
B14: 2.1 | C14: IMPOSTOS S/ VENDAS | E14: =SUM(LARM:RM!E14) -> 0 | F14: =SUM(LARM:RM!F14) -> 0 | G14: =SUM(LARM:RM!G14) -> 0 | H14: =SUM(LARM:RM!H14) -> 0 | I14: =SUM(LARM:RM!I14) -> 0 | J14: =SUM(LARM:RM!J14) -> 0 | K14: =SUM(LARM:RM!K14) -> 0 | L14: =SUM(LARM:RM!L14) -> 0 | ... AI14: =SUM(LARM:RM!AI14) -> 0 | AJ14: =SUM(E14:AI14) -> -52873.83 | AK14: =SUM(LARM:RM!AK14) -> 0 | AL14: =SUM(LARM:RM!AL14) -> 0 | AM14: =SUM(LARM:RM!AM14) -> 0 | AN14: =SUM(LARM:RM!AN14) -> 0 | AO14: =SUM(LARM:RM!AO14) -> 0 | AP14: =SUM(LARM:RM!AP14) -> 0 | AQ14: =SUM(LARM:RM!AQ14) -> 0 | AR14: =SUM(LARM:RM!AR14) -> 0 | ... BO14: =SUM(LARM:RM!BO14) -> 0 | BP14: =SUM(AK14:BO14) -> -12641.7 | BQ14: =SUM(LARM:RM!BQ14) -> 0 | BR14: =SUM(LARM:RM!BR14) -> 0 | BS14: =SUM(LARM:RM!BS14) -> 0 | BT14: =SUM(LARM:RM!BT14) -> 0 | BU14: =SUM(LARM:RM!BU14) -> 0 | BV14: =SUM(LARM:RM!BV14) -> 0 | BW14: =SUM(LARM:RM!BW14) -> 0 | BX14: =SUM(LARM:RM!BX14) -> 0 | ... CU14: =SUM(LARM:RM!CU14) -> 0 | CV14: =SUM(BQ14:CU14) -> -10165.49 | CW14: =SUM(LARM:RM!CW14) -> 0 | CX14: =SUM(LARM:RM!CX14) -> 0 | CY14: =SUM(LARM:RM!CY14) -> 0 | CZ14: =SUM(LARM:RM!CZ14) -> 0 | DA14: =SUM(LARM:RM!DA14) -> 0 | DB14: =SUM(LARM:RM!DB14) -> 0 | DC14: =SUM(LARM:RM!DC14) -> 0 | DD14: =SUM(LARM:RM!DD14) -> 0 | ... EA14: =SUM(LARM:RM!EA14) -> 0 | EB14: =SUM(CW14:EA14) -> -36470.21 | EC14: =SUM(LARM:RM!EC14) -> 0 | ED14: =SUM(LARM:RM!ED14) -> 0 | EE14: =SUM(LARM:RM!EE14) -> 0 | EF14: =SUM(LARM:RM!EF14) -> 0 | EG14: =SUM(LARM:RM!EG14) -> 0 | EH14: =SUM(LARM:RM!EH14) -> 0 | EI14: =SUM(LARM:RM!EI14) -> 0 | EJ14: =SUM(LARM:RM!EJ14) -> 0 | ... FG14: =SUM(LARM:RM!FG14) -> 0 | FH14: =SUM(EC14:FG14) -> -10039.91 | FI14: =SUM(LARM:RM!FI14) -> 0 | FJ14: =SUM(LARM:RM!FJ14) -> 0 | FK14: =SUM(LARM:RM!FK14) -> 0 | FL14: =SUM(LARM:RM!FL14) -> 0 | FM14: =SUM(LARM:RM!FM14) -> 0 | FN14: =SUM(LARM:RM!FN14) -> 0 | FO14: =SUM(LARM:RM!FO14) -> 0 | FP14: =SUM(LARM:RM!FP14) -> 0 | ... GM14: =SUM(LARM:RM!GM14) -> 0 | GN14: =SUM(FI14:GM14) -> -11839.47 | GO14: =SUM(LARM:RM!GO14) -> 0 | GP14: =SUM(LARM:RM!GP14) -> 0 | GQ14: =SUM(LARM:RM!GQ14) -> 0 | GR14: =SUM(LARM:RM!GR14) -> 0 | GS14: =SUM(LARM:RM!GS14) -> 0 | GT14: =SUM(LARM:RM!GT14) -> 0 | GU14: =SUM(LARM:RM!GU14) -> 0 | GV14: =SUM(LARM:RM!GV14) -> 0 | ... HS14: =SUM(LARM:RM!HS14) -> 0 | HT14: =SUM(GO14:HS14) -> -34432.94 | HU14: =SUM(LARM:RM!HU14) -> 0 | HV14: =SUM(LARM:RM!HV14) -> 0 | HW14: =SUM(LARM:RM!HW14) -> 0 | HX14: =SUM(LARM:RM!HX14) -> 0 | HY14: =SUM(LARM:RM!HY14) -> 0 | HZ14: =SUM(LARM:RM!HZ14) -> 0 | IA14: =SUM(LARM:RM!IA14) -> 0 | IB14: =SUM(LARM:RM!IB14) -> 0 | ... IY14: =SUM(LARM:RM!IY14) -> 0 | IZ14: =SUM(HU14:IY14) -> -19556.13 | JA14: =SUM(LARM:RM!JA14) -> 0 | JB14: =SUM(LARM:RM!JB14) -> 0 | JC14: =SUM(LARM:RM!JC14) -> 0 | JD14: =SUM(LARM:RM!JD14) -> 0 | JE14: =SUM(LARM:RM!JE14) -> 0 | JF14: =SUM(LARM:RM!JF14) -> 0 | JG14: =SUM(LARM:RM!JG14) -> 0 | JH14: =SUM(LARM:RM!JH14) -> 0 | ... KE14: =SUM(LARM:RM!KE14) -> 0 | KF14: =SUM(JA14:KE14) -> -11435.29 | KG14: =SUM(LARM:RM!KG14) -> 0 | KH14: =SUM(LARM:RM!KH14) -> 0 | KI14: =SUM(LARM:RM!KI14) -> 0 | KJ14: =SUM(LARM:RM!KJ14) -> 0 | KK14: =SUM(LARM:RM!KK14) -> 0 | KL14: =SUM(LARM:RM!KL14) -> 0 | KM14: =SUM(LARM:RM!KM14) -> 0 | KN14: =SUM(LARM:RM!KN14) -> 0 | ... LK14: =SUM(LARM:RM!LK14) -> 0 | LL14: =SUM(KG14:LK14) -> -29433.25 | LM14: =SUM(LARM:RM!LM14) -> 0 | LN14: =SUM(LARM:RM!LN14) -> 0 | LO14: =SUM(LARM:RM!LO14) -> 0 | LP14: =SUM(LARM:RM!LP14) -> 0 | LQ14: =SUM(LARM:RM!LQ14) -> 0 | LR14: =SUM(LARM:RM!LR14) -> 0 | LS14: =SUM(LARM:RM!LS14) -> 0 | LT14: =SUM(LARM:RM!LT14) -> 0 | ... MQ14: =SUM(LARM:RM!MQ14) -> 0 | MR14: =SUM(LM14:MQ14) -> -7812.9 | MS14: =SUM(LARM:RM!MS14) -> 0 | MT14: =SUM(LARM:RM!MT14) -> 0 | MU14: =SUM(LARM:RM!MU14) -> 0 | MV14: =SUM(LARM:RM!MV14) -> 0 | MW14: =SUM(LARM:RM!MW14) -> 0 | MX14: =SUM(LARM:RM!MX14) -> 0 | MY14: =SUM(LARM:RM!MY14) -> 0 | MZ14: =SUM(LARM:RM!MZ14) -> 0 | ... NW14: =SUM(LARM:RM!NW14) -> 0 | NX14: =SUM(MS14:NW14) -> -7812.9 | NZ14: =AJ14+BP14+CV14+EB14+FH14+GN14+HT14+IZ14+KF14+LL14+MR14+NX14 -> -244514.02 | OA14: =SUM(OI14:OP14) -> -196961.37 | OB14: =IF(OA14=0,"",((NZ14/OA14)-1)*-1) -> -0.24143135 | OG14: IMPOSTOS S/ VENDAS | OI14: =SUM(LARM:RM!OI14) -> -28543.78 | OJ14: =SUM(LARM:RM!OJ14) -> -31012.46 | OK14: =SUM(LARM:RM!OK14) -> -14258.97 | OL14: =SUM(LARM:RM!OL14) -> -47277.71 | OM14: =SUM(LARM:RM!OM14) -> -10039.91 | ON14: =SUM(LARM:RM!ON14) -> -11839.47 | OO14: =SUM(LARM:RM!OO14) -> -34432.94 | OP14: =SUM(LARM:RM!OP14) -> -19556.13 | ... OT14: =SUM(LARM:RM!OT14) -> -7812.9 | OV14: =SUM(OI14:OT14) -> -253455.71
OB15: =IF(OA15=0,"",((NZ15/OA15)-1)*-1)
C16: Receita Líquida | E16: =E7+E12 -> 0 | F16: =F7+F12 -> 5609.2 | G16: =G7+G12 -> 0 | H16: =H7+H12 -> 0 | I16: =I7+I12 -> 13569.03 | J16: =J7+J12 -> 42403.73 | K16: =K7+K12 -> 6934.1 | L16: =L7+L12 -> 4030.18 | ... NX16: =NX7+NX12 -> 244869.35 | NZ16: =NZ7+NZ12 -> 3435375.4 | OA16: =OA7+OA12 -> 2158942.6 | OB16: =IF(OA16=0,"",((NZ16/OA16)-1)*-1) -> -0.59123052 | OG16: Receita Líquida | OI16: =OI7+OI12 -> 217379.99 | OJ16: =OJ7+OJ12 -> 252305.45 | OK16: =OK7+OK12 -> 420496.21 | OL16: =OL7+OL12 -> 246269.17 | OM16: =OM7+OM12 -> 289054.34 | ON16: =ON7+ON12 -> 280910.71 | OO16: =OO7+OO12 -> 271946.52 | OP16: =OP7+OP12 -> 430793.22 | ... OT16: =OT7+OT12 -> 346415.96 | OV16: =OV7+OV12 -> 3708083.6
B18: 4. | C18: Despesas Gerais e Administrativas | E18: =SUM(E19:E31) -> 0 | F18: =SUM(F19:F31) -> -67226.89 | G18: =SUM(G19:G31) -> 0 | H18: =SUM(H19:H31) -> 0 | I18: =SUM(I19:I31) -> -1169.24 | J18: =SUM(J19:J31) -> -925.94 | K18: =SUM(K19:K31) -> -16863.94 | L18: =SUM(L19:L31) -> -29245.09 | ... NX18: =SUM(NX19:NX31) -> -513052.46 | NZ18: =SUM(NZ19:NZ31) -> -5451172.4 | OA18: =OA19+OA20+OA21+OA22+OA23+OA24+OA25+OA26+OA27+OA28+OA29 -> -3164894.4 | OB18: =IF(OA18=0,"",((NZ18/OA18)-1)*-1) -> -0.7223868 | OG18: Despesas Gerais e Administrativas | OI18: =SUM(OI19:OI31) -> -452359.82 | OJ18: =SUM(OJ19:OJ31) -> -463922.99 | OK18: =SUM(OK19:OK31) -> -496965.19 | OL18: =SUM(OL19:OL31) -> -385228.73 | OM18: =SUM(OM19:OM31) -> -662378.39 | ON18: =SUM(ON19:ON31) -> -386553.25 | OO18: =SUM(OO19:OO31) -> -347842.85 | OP18: =SUM(OP19:OP31) -> -423415.81 | ... OT18: =SUM(OT19:OT31) -> -517533.53 | OV18: =SUM(OV19:OV31) -> -5372977.7
B19: 4.1 | C19: DESPESAS COM PESSOAL (1) | E19: =SUM(LARM:RM!E19) -> 0 | F19: =SUM(LARM:RM!F19) -> 0 | G19: =SUM(LARM:RM!G19) -> 0 | H19: =SUM(LARM:RM!H19) -> 0 | I19: =SUM(LARM:RM!I19) -> 0 | J19: =SUM(LARM:RM!J19) -> 0 | K19: =SUM(LARM:RM!K19) -> 0 | L19: =SUM(LARM:RM!L19) -> 0 | ... AI19: =SUM(LARM:RM!AI19) -> 0 | AJ19: =SUM(E19:AI19) -> -110882.46 | AK19: =SUM(LARM:RM!AK19) -> 0 | AL19: =SUM(LARM:RM!AL19) -> 0 | AM19: =SUM(LARM:RM!AM19) -> 0 | AN19: =SUM(LARM:RM!AN19) -> 0 | AO19: =SUM(LARM:RM!AO19) -> 0 | AP19: =SUM(LARM:RM!AP19) -> 0 | AQ19: =SUM(LARM:RM!AQ19) -> 0 | AR19: =SUM(LARM:RM!AR19) -> 0 | ... BO19: =SUM(LARM:RM!BO19) -> 0 | BP19: =SUM(AK19:BO19) -> -103879.25 | BQ19: =SUM(LARM:RM!BQ19) -> 0 | BR19: =SUM(LARM:RM!BR19) -> 0 | BS19: =SUM(LARM:RM!BS19) -> 0 | BT19: =SUM(LARM:RM!BT19) -> 0 | BU19: =SUM(LARM:RM!BU19) -> 0 | BV19: =SUM(LARM:RM!BV19) -> 0 | BW19: =SUM(LARM:RM!BW19) -> 0 | BX19: =SUM(LARM:RM!BX19) -> 0 | ... CU19: =SUM(LARM:RM!CU19) -> 0 | CV19: =SUM(BQ19:CU19) -> -103543.4 | CW19: =SUM(LARM:RM!CW19) -> 0 | CX19: =SUM(LARM:RM!CX19) -> 0 | CY19: =SUM(LARM:RM!CY19) -> 0 | CZ19: =SUM(LARM:RM!CZ19) -> 0 | DA19: =SUM(LARM:RM!DA19) -> 0 | DB19: =SUM(LARM:RM!DB19) -> 0 | DC19: =SUM(LARM:RM!DC19) -> 0 | DD19: =SUM(LARM:RM!DD19) -> 0 | ... EA19: =SUM(LARM:RM!EA19) -> 0 | EB19: =SUM(CW19:EA19) -> -97907.42 | EC19: =SUM(LARM:RM!EC19) -> 0 | ED19: =SUM(LARM:RM!ED19) -> 0 | EE19: =SUM(LARM:RM!EE19) -> 0 | EF19: =SUM(LARM:RM!EF19) -> 0 | EG19: =SUM(LARM:RM!EG19) -> 0 | EH19: =SUM(LARM:RM!EH19) -> 0 | EI19: =SUM(LARM:RM!EI19) -> 0 | EJ19: =SUM(LARM:RM!EJ19) -> 0 | ... FG19: =SUM(LARM:RM!FG19) -> 0 | FH19: =SUM(EC19:FG19) -> -109473.56 | FI19: =SUM(LARM:RM!FI19) -> 0 | FJ19: =SUM(LARM:RM!FJ19) -> 0 | FK19: =SUM(LARM:RM!FK19) -> 0 | FL19: =SUM(LARM:RM!FL19) -> 0 | FM19: =SUM(LARM:RM!FM19) -> 0 | FN19: =SUM(LARM:RM!FN19) -> 0 | FO19: =SUM(LARM:RM!FO19) -> 0 | FP19: =SUM(LARM:RM!FP19) -> 0 | ... GM19: =SUM(LARM:RM!GM19) -> 0 | GN19: =SUM(FI19:GM19) -> -113995.28 | GO19: =SUM(LARM:RM!GO19) -> 0 | GP19: =SUM(LARM:RM!GP19) -> 0 | GQ19: =SUM(LARM:RM!GQ19) -> 0 | GR19: =SUM(LARM:RM!GR19) -> 0 | GS19: =SUM(LARM:RM!GS19) -> 0 | GT19: =SUM(LARM:RM!GT19) -> 0 | GU19: =SUM(LARM:RM!GU19) -> 0 | GV19: =SUM(LARM:RM!GV19) -> 0 | ... HS19: =SUM(LARM:RM!HS19) -> 0 | HT19: =SUM(GO19:HS19) -> -110883.44 | HU19: =SUM(LARM:RM!HU19) -> -1356.3 | HV19: =SUM(LARM:RM!HV19) -> 0 | HW19: =SUM(LARM:RM!HW19) -> 0 | HX19: =SUM(LARM:RM!HX19) -> 0 | HY19: =SUM(LARM:RM!HY19) -> 0 | HZ19: =SUM(LARM:RM!HZ19) -> 0 | IA19: =SUM(LARM:RM!IA19) -> -726.58 | IB19: =SUM(LARM:RM!IB19) -> 0 | ... IY19: =SUM(LARM:RM!IY19) -> 0 | IZ19: =SUM(HU19:IY19) -> -119898.27 | JA19: =SUM(LARM:RM!JA19) -> 0 | JB19: =SUM(LARM:RM!JB19) -> 0 | JC19: =SUM(LARM:RM!JC19) -> 0 | JD19: =SUM(LARM:RM!JD19) -> 0 | JE19: =SUM(LARM:RM!JE19) -> 0 | JF19: =SUM(LARM:RM!JF19) -> 0 | JG19: =SUM(LARM:RM!JG19) -> 0 | JH19: =SUM(LARM:RM!JH19) -> 0 | ... KE19: =SUM(LARM:RM!KE19) -> 0 | KF19: =SUM(JA19:KE19) -> -115799.65 | KG19: =SUM(LARM:RM!KG19) -> 0 | KH19: =SUM(LARM:RM!KH19) -> 0 | KI19: =SUM(LARM:RM!KI19) -> 0 | KJ19: =SUM(LARM:RM!KJ19) -> 0 | KK19: =SUM(LARM:RM!KK19) -> 0 | KL19: =SUM(LARM:RM!KL19) -> 0 | KM19: =SUM(LARM:RM!KM19) -> 0 | KN19: =SUM(LARM:RM!KN19) -> 0 | ... LK19: =SUM(LARM:RM!LK19) -> 0 | LL19: =SUM(KG19:LK19) -> -111574.14 | LM19: =SUM(LARM:RM!LM19) -> 0 | LN19: =SUM(LARM:RM!LN19) -> 0 | LO19: =SUM(LARM:RM!LO19) -> 0 | LP19: =SUM(LARM:RM!LP19) -> 0 | LQ19: =SUM(LARM:RM!LQ19) -> 0 | LR19: =SUM(LARM:RM!LR19) -> 0 | LS19: =SUM(LARM:RM!LS19) -> 0 | LT19: =SUM(LARM:RM!LT19) -> 0 | ... MQ19: =SUM(LARM:RM!MQ19) -> 0 | MR19: =SUM(LM19:MQ19) -> -150447.51 | MS19: =SUM(LARM:RM!MS19) -> 0 | MT19: =SUM(LARM:RM!MT19) -> -661.45 | MU19: =SUM(LARM:RM!MU19) -> 0 | MV19: =SUM(LARM:RM!MV19) -> 0 | MW19: =SUM(LARM:RM!MW19) -> 0 | MX19: =SUM(LARM:RM!MX19) -> 0 | MY19: =SUM(LARM:RM!MY19) -> -2493.99 | MZ19: =SUM(LARM:RM!MZ19) -> 0 | ... NW19: =SUM(LARM:RM!NW19) -> 0 | NX19: =SUM(MS19:NW19) -> -200850.35 | NZ19: =AJ19+BP19+CV19+EB19+FH19+GN19+HT19+IZ19+KF19+LL19+MR19+NX19 -> -1449134.7 | OA19: =SUM(OI19:OP19) -> -911269.45 | OB19: =IF(OA19=0,"",((NZ19/OA19)-1)*-1) -> -0.59023737 | OG19: DESPESAS COM PESSOAL (1) | OI19: =SUM(LARM:RM!OI19) -> -111635.3 | OJ19: =SUM(LARM:RM!OJ19) -> -112667.6 | OK19: =SUM(LARM:RM!OK19) -> -110044.48 | OL19: =SUM(LARM:RM!OL19) -> -112962 | OM19: =SUM(LARM:RM!OM19) -> -129511.36 | ON19: =SUM(LARM:RM!ON19) -> -107974.74 | OO19: =SUM(LARM:RM!OO19) -> -107164.06 | OP19: =SUM(LARM:RM!OP19) -> -119309.9 | ... OT19: =SUM(LARM:RM!OT19) -> -208561.27 | OV19: =SUM(OI19:OT19) -> -1498973.6
B20: 4.2 | C20: OCUPACÃO (2) | E20: =SUM(LARM:RM!E20) -> 0 | F20: =SUM(LARM:RM!F20) -> -23096.54 | G20: =SUM(LARM:RM!G20) -> 0 | H20: =SUM(LARM:RM!H20) -> 0 | I20: =SUM(LARM:RM!I20) -> 0 | J20: =SUM(LARM:RM!J20) -> 0 | K20: =SUM(LARM:RM!K20) -> -6591.13 | L20: =SUM(LARM:RM!L20) -> -3680 | ... AI20: =SUM(LARM:RM!AI20) -> 0 | AJ20: =SUM(E20:AI20) -> -46655.23 | AK20: =SUM(LARM:RM!AK20) -> 0 | AL20: =SUM(LARM:RM!AL20) -> -31307.19 | AM20: =SUM(LARM:RM!AM20) -> 0 | AN20: =SUM(LARM:RM!AN20) -> 0 | AO20: =SUM(LARM:RM!AO20) -> 0 | AP20: =SUM(LARM:RM!AP20) -> 0 | AQ20: =SUM(LARM:RM!AQ20) -> 0 | AR20: =SUM(LARM:RM!AR20) -> 0 | ... BO20: =SUM(LARM:RM!BO20) -> 0 | BP20: =SUM(AK20:BO20) -> -37989.34 | BQ20: =SUM(LARM:RM!BQ20) -> 0 | BR20: =SUM(LARM:RM!BR20) -> -23057.46 | BS20: =SUM(LARM:RM!BS20) -> 0 | BT20: =SUM(LARM:RM!BT20) -> 0 | BU20: =SUM(LARM:RM!BU20) -> 0 | BV20: =SUM(LARM:RM!BV20) -> 0 | BW20: =SUM(LARM:RM!BW20) -> 0 | BX20: =SUM(LARM:RM!BX20) -> 0 | ... CU20: =SUM(LARM:RM!CU20) -> 0 | CV20: =SUM(BQ20:CU20) -> -40314.91 | CW20: =SUM(LARM:RM!CW20) -> -25508.45 | CX20: =SUM(LARM:RM!CX20) -> 0 | CY20: =SUM(LARM:RM!CY20) -> 0 | CZ20: =SUM(LARM:RM!CZ20) -> 0 | DA20: =SUM(LARM:RM!DA20) -> 0 | DB20: =SUM(LARM:RM!DB20) -> -7434.76 | DC20: =SUM(LARM:RM!DC20) -> 0 | DD20: =SUM(LARM:RM!DD20) -> 0 | ... EA20: =SUM(LARM:RM!EA20) -> 0 | EB20: =SUM(CW20:EA20) -> -42669.81 | EC20: =SUM(LARM:RM!EC20) -> 0 | ED20: =SUM(LARM:RM!ED20) -> 0 | EE20: =SUM(LARM:RM!EE20) -> 0 | EF20: =SUM(LARM:RM!EF20) -> -25905.95 | EG20: =SUM(LARM:RM!EG20) -> 0 | EH20: =SUM(LARM:RM!EH20) -> -3300.3 | EI20: =SUM(LARM:RM!EI20) -> 0 | EJ20: =SUM(LARM:RM!EJ20) -> 0 | ... FG20: =SUM(LARM:RM!FG20) -> 0 | FH20: =SUM(EC20:FG20) -> -42379.91 | FI20: =SUM(LARM:RM!FI20) -> 0 | FJ20: =SUM(LARM:RM!FJ20) -> -29913.46 | FK20: =SUM(LARM:RM!FK20) -> 0 | FL20: =SUM(LARM:RM!FL20) -> 0 | FM20: =SUM(LARM:RM!FM20) -> 0 | FN20: =SUM(LARM:RM!FN20) -> 0 | FO20: =SUM(LARM:RM!FO20) -> 0 | FP20: =SUM(LARM:RM!FP20) -> 0 | ... GM20: =SUM(LARM:RM!GM20) -> 0 | GN20: =SUM(FI20:GM20) -> -36283.86 | GO20: =SUM(LARM:RM!GO20) -> -29387.02 | GP20: =SUM(LARM:RM!GP20) -> 0 | GQ20: =SUM(LARM:RM!GQ20) -> 0 | GR20: =SUM(LARM:RM!GR20) -> 0 | GS20: =SUM(LARM:RM!GS20) -> 0 | GT20: =SUM(LARM:RM!GT20) -> 0 | GU20: =SUM(LARM:RM!GU20) -> -6222 | GV20: =SUM(LARM:RM!GV20) -> 0 | ... HS20: =SUM(LARM:RM!HS20) -> 0 | HT20: =SUM(GO20:HS20) -> -42307.02 | HU20: =SUM(LARM:RM!HU20) -> -29667.91 | HV20: =SUM(LARM:RM!HV20) -> 0 | HW20: =SUM(LARM:RM!HW20) -> 0 | HX20: =SUM(LARM:RM!HX20) -> 0 | HY20: =SUM(LARM:RM!HY20) -> 0 | HZ20: =SUM(LARM:RM!HZ20) -> 0 | IA20: =SUM(LARM:RM!IA20) -> 0 | IB20: =SUM(LARM:RM!IB20) -> 0 | ... IY20: =SUM(LARM:RM!IY20) -> 0 | IZ20: =SUM(HU20:IY20) -> -40147.91 | JA20: =SUM(LARM:RM!JA20) -> -30006.03 | JB20: =SUM(LARM:RM!JB20) -> 0 | JC20: =SUM(LARM:RM!JC20) -> 0 | JD20: =SUM(LARM:RM!JD20) -> 0 | JE20: =SUM(LARM:RM!JE20) -> -1600 | JF20: =SUM(LARM:RM!JF20) -> 0 | JG20: =SUM(LARM:RM!JG20) -> 0 | JH20: =SUM(LARM:RM!JH20) -> 0 | ... KE20: =SUM(LARM:RM!KE20) -> 0 | KF20: =SUM(JA20:KE20) -> -58954.62 | KG20: =SUM(LARM:RM!KG20) -> -19096 | KH20: =SUM(LARM:RM!KH20) -> 0 | KI20: =SUM(LARM:RM!KI20) -> -8616.67 | KJ20: =SUM(LARM:RM!KJ20) -> 0 | KK20: =SUM(LARM:RM!KK20) -> 0 | KL20: =SUM(LARM:RM!KL20) -> -11016.58 | KM20: =SUM(LARM:RM!KM20) -> 0 | KN20: =SUM(LARM:RM!KN20) -> 0 | ... LK20: =SUM(LARM:RM!LK20) -> 0 | LL20: =SUM(KG20:LK20) -> -52455.25 | LM20: =SUM(LARM:RM!LM20) -> 0 | LN20: =SUM(LARM:RM!LN20) -> 0 | LO20: =SUM(LARM:RM!LO20) -> -18896 | LP20: =SUM(LARM:RM!LP20) -> 0 | LQ20: =SUM(LARM:RM!LQ20) -> -10779.81 | LR20: =SUM(LARM:RM!LR20) -> 0 | LS20: =SUM(LARM:RM!LS20) -> 0 | LT20: =SUM(LARM:RM!LT20) -> 0 | ... MQ20: =SUM(LARM:RM!MQ20) -> 0 | MR20: =SUM(LM20:MQ20) -> -41124.61 | MS20: =SUM(LARM:RM!MS20) -> -12889.37 | MT20: =SUM(LARM:RM!MT20) -> 0 | MU20: =SUM(LARM:RM!MU20) -> -10106 | MV20: =SUM(LARM:RM!MV20) -> 0 | MW20: =SUM(LARM:RM!MW20) -> 0 | MX20: =SUM(LARM:RM!MX20) -> -6126.27 | MY20: =SUM(LARM:RM!MY20) -> 0 | MZ20: =SUM(LARM:RM!MZ20) -> 0 | ... NW20: =SUM(LARM:RM!NW20) -> 0 | NX20: =SUM(MS20:NW20) -> -39869.64 | NZ20: =AJ20+BP20+CV20+EB20+FH20+GN20+HT20+IZ20+KF20+LL20+MR20+NX20 -> -521152.11 | OA20: =SUM(OI20:OP20) -> -353409.24 | OB20: =IF(OA20=0,"",((NZ20/OA20)-1)*-1) -> -0.474642 | OD20: =30963-26696 -> 4267 | OG20: OCUPACÃO (2) | OI20: =SUM(LARM:RM!OI20) -> -57061.97 | OJ20: =SUM(LARM:RM!OJ20) -> -40747.43 | OK20: =SUM(LARM:RM!OK20) -> -43027.53 | OL20: =SUM(LARM:RM!OL20) -> -52087.93 | OM20: =SUM(LARM:RM!OM20) -> -41745.59 | ON20: =SUM(LARM:RM!ON20) -> -36283.86 | OO20: =SUM(LARM:RM!OO20) -> -42307.02 | OP20: =SUM(LARM:RM!OP20) -> -40147.91 | ... OT20: =SUM(LARM:RM!OT20) -> -39869.64 | OV20: =SUM(OI20:OT20) -> -545813.36
B21: 4.3 | C21: UTILIDADES E SERVICOS (3) | E21: =SUM(LARM:RM!E21) -> 0 | F21: =SUM(LARM:RM!F21) -> -467.06 | G21: =SUM(LARM:RM!G21) -> 0 | H21: =SUM(LARM:RM!H21) -> 0 | I21: =SUM(LARM:RM!I21) -> 0 | J21: =SUM(LARM:RM!J21) -> -425.94 | K21: =SUM(LARM:RM!K21) -> 0 | L21: =SUM(LARM:RM!L21) -> -2141.17 | ... AI21: =SUM(LARM:RM!AI21) -> 0 | AJ21: =SUM(E21:AI21) -> -9008.6 | AK21: =SUM(LARM:RM!AK21) -> 0 | AL21: =SUM(LARM:RM!AL21) -> -1083.35 | AM21: =SUM(LARM:RM!AM21) -> 0 | AN21: =SUM(LARM:RM!AN21) -> 0 | AO21: =SUM(LARM:RM!AO21) -> 0 | AP21: =SUM(LARM:RM!AP21) -> -368.15 | AQ21: =SUM(LARM:RM!AQ21) -> 0 | AR21: =SUM(LARM:RM!AR21) -> 0 | ... BO21: =SUM(LARM:RM!BO21) -> 0 | BP21: =SUM(AK21:BO21) -> -9002.28 | BQ21: =SUM(LARM:RM!BQ21) -> 0 | BR21: =SUM(LARM:RM!BR21) -> -1078.46 | BS21: =SUM(LARM:RM!BS21) -> 0 | BT21: =SUM(LARM:RM!BT21) -> 0 | BU21: =SUM(LARM:RM!BU21) -> -518.11 | BV21: =SUM(LARM:RM!BV21) -> -640.46 | BW21: =SUM(LARM:RM!BW21) -> 0 | BX21: =SUM(LARM:RM!BX21) -> 0 | ... CU21: =SUM(LARM:RM!CU21) -> 0 | CV21: =SUM(BQ21:CU21) -> -10324.54 | CW21: =SUM(LARM:RM!CW21) -> -1047.29 | CX21: =SUM(LARM:RM!CX21) -> 0 | CY21: =SUM(LARM:RM!CY21) -> 0 | CZ21: =SUM(LARM:RM!CZ21) -> 0 | DA21: =SUM(LARM:RM!DA21) -> 0 | DB21: =SUM(LARM:RM!DB21) -> -1715.24 | DC21: =SUM(LARM:RM!DC21) -> 0 | DD21: =SUM(LARM:RM!DD21) -> -682.88 | ... EA21: =SUM(LARM:RM!EA21) -> 0 | EB21: =SUM(CW21:EA21) -> -7949.8 | EC21: =SUM(LARM:RM!EC21) -> 0 | ED21: =SUM(LARM:RM!ED21) -> 0 | EE21: =SUM(LARM:RM!EE21) -> 0 | EF21: =SUM(LARM:RM!EF21) -> -2005.31 | EG21: =SUM(LARM:RM!EG21) -> 0 | EH21: =SUM(LARM:RM!EH21) -> 0 | EI21: =SUM(LARM:RM!EI21) -> 0 | EJ21: =SUM(LARM:RM!EJ21) -> 0 | ... FG21: =SUM(LARM:RM!FG21) -> 0 | FH21: =SUM(EC21:FG21) -> -6502.56 | FI21: =SUM(LARM:RM!FI21) -> 0 | FJ21: =SUM(LARM:RM!FJ21) -> -518.98 | FK21: =SUM(LARM:RM!FK21) -> -536.4 | FL21: =SUM(LARM:RM!FL21) -> 0 | FM21: =SUM(LARM:RM!FM21) -> 0 | FN21: =SUM(LARM:RM!FN21) -> -386.3 | FO21: =SUM(LARM:RM!FO21) -> 0 | FP21: =SUM(LARM:RM!FP21) -> 0 | ... GM21: =SUM(LARM:RM!GM21) -> 0 | GN21: =SUM(FI21:GM21) -> -8110.67 | GO21: =SUM(LARM:RM!GO21) -> -398.57 | GP21: =SUM(LARM:RM!GP21) -> 0 | GQ21: =SUM(LARM:RM!GQ21) -> 0 | GR21: =SUM(LARM:RM!GR21) -> 0 | GS21: =SUM(LARM:RM!GS21) -> 0 | GT21: =SUM(LARM:RM!GT21) -> 0 | GU21: =SUM(LARM:RM!GU21) -> -1068.1 | GV21: =SUM(LARM:RM!GV21) -> -1306.92 | ... HS21: =SUM(LARM:RM!HS21) -> 0 | HT21: =SUM(GO21:HS21) -> -7661.79 | HU21: =SUM(LARM:RM!HU21) -> -417.32 | HV21: =SUM(LARM:RM!HV21) -> 0 | HW21: =SUM(LARM:RM!HW21) -> 0 | HX21: =SUM(LARM:RM!HX21) -> 0 | HY21: =SUM(LARM:RM!HY21) -> -768.02 | HZ21: =SUM(LARM:RM!HZ21) -> 0 | IA21: =SUM(LARM:RM!IA21) -> 0 | IB21: =SUM(LARM:RM!IB21) -> -1027.86 | ... IY21: =SUM(LARM:RM!IY21) -> 0 | IZ21: =SUM(HU21:IY21) -> -8653.22 | JA21: =SUM(LARM:RM!JA21) -> -896.91 | JB21: =SUM(LARM:RM!JB21) -> 0 | JC21: =SUM(LARM:RM!JC21) -> 0 | JD21: =SUM(LARM:RM!JD21) -> 0 | JE21: =SUM(LARM:RM!JE21) -> 0 | JF21: =SUM(LARM:RM!JF21) -> 0 | JG21: =SUM(LARM:RM!JG21) -> 0 | JH21: =SUM(LARM:RM!JH21) -> -387.39 | ... KE21: =SUM(LARM:RM!KE21) -> 0 | KF21: =SUM(JA21:KE21) -> -8872.97 | KG21: =SUM(LARM:RM!KG21) -> -100.06 | KH21: =SUM(LARM:RM!KH21) -> 0 | KI21: =SUM(LARM:RM!KI21) -> 0 | KJ21: =SUM(LARM:RM!KJ21) -> 0 | KK21: =SUM(LARM:RM!KK21) -> 0 | KL21: =SUM(LARM:RM!KL21) -> -810.54 | KM21: =SUM(LARM:RM!KM21) -> 0 | KN21: =SUM(LARM:RM!KN21) -> -2463.91 | ... LK21: =SUM(LARM:RM!LK21) -> 0 | LL21: =SUM(KG21:LK21) -> -8680.33 | LM21: =SUM(LARM:RM!LM21) -> 0 | LN21: =SUM(LARM:RM!LN21) -> 0 | LO21: =SUM(LARM:RM!LO21) -> -475.23 | LP21: =SUM(LARM:RM!LP21) -> 0 | LQ21: =SUM(LARM:RM!LQ21) -> -488.75 | LR21: =SUM(LARM:RM!LR21) -> 0 | LS21: =SUM(LARM:RM!LS21) -> 0 | LT21: =SUM(LARM:RM!LT21) -> 0 | ... MQ21: =SUM(LARM:RM!MQ21) -> 0 | MR21: =SUM(LM21:MQ21) -> -9424.26 | MS21: =SUM(LARM:RM!MS21) -> 0 | MT21: =SUM(LARM:RM!MT21) -> 0 | MU21: =SUM(LARM:RM!MU21) -> -910.42 | MV21: =SUM(LARM:RM!MV21) -> -150 | MW21: =SUM(LARM:RM!MW21) -> -621.57 | MX21: =SUM(LARM:RM!MX21) -> -310.05 | MY21: =SUM(LARM:RM!MY21) -> 0 | MZ21: =SUM(LARM:RM!MZ21) -> -410 | ... NW21: =SUM(LARM:RM!NW21) -> 0 | NX21: =SUM(MS21:NW21) -> -7829.66 | NZ21: =AJ21+BP21+CV21+EB21+FH21+GN21+HT21+IZ21+KF21+LL21+MR21+NX21 -> -102020.68 | OA21: =SUM(OI21:OP21) -> -56334.5 | OB21: =IF(OA21=0,"",((NZ21/OA21)-1)*-1) -> -0.81098048 | OG21: UTILIDADES E SERVICOS (3) | OI21: =SUM(LARM:RM!OI21) -> -4204.94 | OJ21: =SUM(LARM:RM!OJ21) -> -8275.42 | OK21: =SUM(LARM:RM!OK21) -> -9040.77 | OL21: =SUM(LARM:RM!OL21) -> -7889.33 | OM21: =SUM(LARM:RM!OM21) -> -5830.58 | ON21: =SUM(LARM:RM!ON21) -> -6999.93 | OO21: =SUM(LARM:RM!OO21) -> -6551.05 | OP21: =SUM(LARM:RM!OP21) -> -7542.48 | ... OT21: =SUM(LARM:RM!OT21) -> -6399.81 | OV21: =SUM(OI21:OT21) -> -86757.08
B22: 4.4 | C22: DESPESAS GERAIS/TERCEIROS (4) | E22: =SUM(LARM:RM!E22) -> 0 | F22: =SUM(LARM:RM!F22) -> -2880 | G22: =SUM(LARM:RM!G22) -> 0 | H22: =SUM(LARM:RM!H22) -> 0 | I22: =SUM(LARM:RM!I22) -> -958.74 | J22: =SUM(LARM:RM!J22) -> -500 | K22: =SUM(LARM:RM!K22) -> -2846 | L22: =SUM(LARM:RM!L22) -> -1001.87 | ... AI22: =SUM(LARM:RM!AI22) -> 0 | AJ22: =SUM(E22:AI22) -> -104190.97 | AK22: =SUM(LARM:RM!AK22) -> 0 | AL22: =SUM(LARM:RM!AL22) -> -8171.74 | AM22: =SUM(LARM:RM!AM22) -> -1022.64 | AN22: =SUM(LARM:RM!AN22) -> 0 | AO22: =SUM(LARM:RM!AO22) -> 0 | AP22: =SUM(LARM:RM!AP22) -> -5000 | AQ22: =SUM(LARM:RM!AQ22) -> 0 | AR22: =SUM(LARM:RM!AR22) -> 0 | ... BO22: =SUM(LARM:RM!BO22) -> 0 | BP22: =SUM(AK22:BO22) -> -66884.41 | BQ22: =SUM(LARM:RM!BQ22) -> 0 | BR22: =SUM(LARM:RM!BR22) -> -5859.08 | BS22: =SUM(LARM:RM!BS22) -> -3975.52 | BT22: =SUM(LARM:RM!BT22) -> 0 | BU22: =SUM(LARM:RM!BU22) -> 0 | BV22: =SUM(LARM:RM!BV22) -> -8001.8 | BW22: =SUM(LARM:RM!BW22) -> 0 | BX22: =SUM(LARM:RM!BX22) -> 0 | ... CU22: =SUM(LARM:RM!CU22) -> 0 | CV22: =SUM(BQ22:CU22) -> -84437.182 | CW22: =SUM(LARM:RM!CW22) -> -3019.78 | CX22: =SUM(LARM:RM!CX22) -> -771.7 | CY22: =SUM(LARM:RM!CY22) -> 0 | CZ22: =SUM(LARM:RM!CZ22) -> 0 | DA22: =SUM(LARM:RM!DA22) -> 0 | DB22: =SUM(LARM:RM!DB22) -> -5393.02 | DC22: =SUM(LARM:RM!DC22) -> 0 | DD22: =SUM(LARM:RM!DD22) -> -13994.03 | ... EA22: =SUM(LARM:RM!EA22) -> 0 | EB22: =SUM(CW22:EA22) -> -64251.31 | EC22: =SUM(LARM:RM!EC22) -> 0 | ED22: =SUM(LARM:RM!ED22) -> 0 | EE22: =SUM(LARM:RM!EE22) -> 0 | EF22: =SUM(LARM:RM!EF22) -> -1393.86 | EG22: =SUM(LARM:RM!EG22) -> 0 | EH22: =SUM(LARM:RM!EH22) -> -1018.24 | EI22: =SUM(LARM:RM!EI22) -> 0 | EJ22: =SUM(LARM:RM!EJ22) -> 0 | ... FG22: =SUM(LARM:RM!FG22) -> 0 | FH22: =SUM(EC22:FG22) -> -80509.79 | FI22: =SUM(LARM:RM!FI22) -> 0 | FJ22: =SUM(LARM:RM!FJ22) -> -4840.8 | FK22: =SUM(LARM:RM!FK22) -> 0 | FL22: =SUM(LARM:RM!FL22) -> 0 | FM22: =SUM(LARM:RM!FM22) -> 0 | FN22: =SUM(LARM:RM!FN22) -> -78.58 | FO22: =SUM(LARM:RM!FO22) -> 0 | FP22: =SUM(LARM:RM!FP22) -> 0 | ... GM22: =SUM(LARM:RM!GM22) -> 0 | GN22: =SUM(FI22:GM22) -> -75465.22 | GO22: =SUM(LARM:RM!GO22) -> -3340.5 | GP22: =SUM(LARM:RM!GP22) -> 0 | GQ22: =SUM(LARM:RM!GQ22) -> 0 | GR22: =SUM(LARM:RM!GR22) -> 0 | GS22: =SUM(LARM:RM!GS22) -> 0 | GT22: =SUM(LARM:RM!GT22) -> 0 | GU22: =SUM(LARM:RM!GU22) -> -1654.4 | GV22: =SUM(LARM:RM!GV22) -> -5000 | ... HS22: =SUM(LARM:RM!HS22) -> 0 | HT22: =SUM(GO22:HS22) -> -57221.49 | HU22: =SUM(LARM:RM!HU22) -> -24075.62 | HV22: =SUM(LARM:RM!HV22) -> 0 | HW22: =SUM(LARM:RM!HW22) -> 0 | HX22: =SUM(LARM:RM!HX22) -> -660.7 | HY22: =SUM(LARM:RM!HY22) -> -5950 | HZ22: =SUM(LARM:RM!HZ22) -> 0 | IA22: =SUM(LARM:RM!IA22) -> 0 | IB22: =SUM(LARM:RM!IB22) -> 0 | ... IY22: =SUM(LARM:RM!IY22) -> 0 | IZ22: =SUM(HU22:IY22) -> -113521.79 | JA22: =SUM(LARM:RM!JA22) -> -3830 | JB22: =SUM(LARM:RM!JB22) -> 0 | JC22: =SUM(LARM:RM!JC22) -> 0 | JD22: =SUM(LARM:RM!JD22) -> -5000 | JE22: =SUM(LARM:RM!JE22) -> -1310 | JF22: =SUM(LARM:RM!JF22) -> 0 | JG22: =SUM(LARM:RM!JG22) -> 0 | JH22: =SUM(LARM:RM!JH22) -> -32730.9 | ... KE22: =SUM(LARM:RM!KE22) -> 0 | KF22: =SUM(JA22:KE22) -> -77885.54 | KG22: =SUM(LARM:RM!KG22) -> -43127 | KH22: =SUM(LARM:RM!KH22) -> 0 | KI22: =SUM(LARM:RM!KI22) -> 0 | KJ22: =SUM(LARM:RM!KJ22) -> 0 | KK22: =SUM(LARM:RM!KK22) -> 0 | KL22: =SUM(LARM:RM!KL22) -> -5950 | KM22: =SUM(LARM:RM!KM22) -> 0 | KN22: =SUM(LARM:RM!KN22) -> -780 | ... LK22: =SUM(LARM:RM!LK22) -> 0 | LL22: =SUM(KG22:LK22) -> -99640.55 | LM22: =SUM(LARM:RM!LM22) -> 0 | LN22: =SUM(LARM:RM!LN22) -> 0 | LO22: =SUM(LARM:RM!LO22) -> -8233.6 | LP22: =SUM(LARM:RM!LP22) -> 0 | LQ22: =SUM(LARM:RM!LQ22) -> -1215 | LR22: =SUM(LARM:RM!LR22) -> -5000 | LS22: =SUM(LARM:RM!LS22) -> 0 | LT22: =SUM(LARM:RM!LT22) -> 0 | ... MQ22: =SUM(LARM:RM!MQ22) -> 0 | MR22: =SUM(LM22:MQ22) -> -51655.35 | MS22: =SUM(LARM:RM!MS22) -> -2550 | MT22: =SUM(LARM:RM!MT22) -> 0 | MU22: =SUM(LARM:RM!MU22) -> -1197.47 | MV22: =SUM(LARM:RM!MV22) -> 0 | MW22: =SUM(LARM:RM!MW22) -> -265 | MX22: =SUM(LARM:RM!MX22) -> 0 | MY22: =SUM(LARM:RM!MY22) -> 0 | MZ22: =SUM(LARM:RM!MZ22) -> 0 | ... NW22: =SUM(LARM:RM!NW22) -> 0 | NX22: =SUM(MS22:NW22) -> -96240.37 | NZ22: =AJ22+BP22+CV22+EB22+FH22+GN22+HT22+IZ22+KF22+LL22+MR22+NX22 -> -971903.97 | OA22: =SUM(OI22:OP22) -> -575353.81 | OB22: =IF(OA22=0,"",((NZ22/OA22)-1)*-1) -> -0.68922836 | OG22: DESPESAS GERAIS/TERCEIROS (4) | OI22: =SUM(LARM:RM!OI22) -> -69833.83 | OJ22: =SUM(LARM:RM!OJ22) -> -71248.07 | OK22: =SUM(LARM:RM!OK22) -> -60634.41 | OL22: =SUM(LARM:RM!OL22) -> -62994.01 | OM22: =SUM(LARM:RM!OM22) -> -83034.99 | ON22: =SUM(LARM:RM!ON22) -> -60465.22 | OO22: =SUM(LARM:RM!OO22) -> -55421.49 | OP22: =SUM(LARM:RM!OP22) -> -111721.79 | ... OT22: =SUM(LARM:RM!OT22) -> -94440.37 | OV22: =SUM(OI22:OT22) -> -893575.62
